Workbook
Name li: '[1]COT A101-LVS-EXT'!$J$19
Name po: '[1]COT A101-LVS-EXT'!$N$18

Sheet CALC_AGENT
D3: METROS | E3: PIES
D4: 1 | E4: 3.28083
C6: ALTURA GEOGRAFICA | D6: METROS (msnm) | E6: PIES
D7: =INGRESO_DATOS_SALA!D5 -> 1 | E7: =CONVERT(D7,"m","ft") -> 3.2808399
C9: SALA 1 | G9: SALA 2 | L9: SALA 3 | P9: SALA 4
C10: LARGO | D10: =INGRESO_DATOS_SALA!D13 -> 1 | E10: =CONVERT(D10,"m","ft") -> 3.2808399 | G10: LARGO | H10: =INGRESO_DATOS_SALA!J13 -> 0 | I10: =CONVERT(H10,"m","ft") -> 0 | L10: LARGO | M10: =INGRESO_DATOS_SALA!N13 -> 0 | N10: =CONVERT(M10,"m","ft") -> 0 | P10: LARGO | Q10: =INGRESO_DATOS_SALA!R13 -> 0 | R10: =CONVERT(Q10,"m","ft") -> 0
C11: ANCHO | D11: =INGRESO_DATOS_SALA!D14 -> 1 | E11: =CONVERT(D11,"m","ft") -> 3.2808399 | G11: ANCHO | H11: =INGRESO_DATOS_SALA!J14 -> 0 | I11: =CONVERT(H11,"m","ft") -> 0 | L11: ANCHO | M11: =INGRESO_DATOS_SALA!N14 -> 0 | N11: =CONVERT(M11,"m","ft") -> 0 | P11: ANCHO | Q11: =INGRESO_DATOS_SALA!R14 -> 0 | R11: =CONVERT(Q11,"m","ft") -> 0
C12: ALTO | D12: =INGRESO_DATOS_SALA!D15 -> 1 | E12: =CONVERT(D12,"m","ft") -> 3.2808399 | G12: ALTO | H12: =INGRESO_DATOS_SALA!J15 -> 0 | I12: =CONVERT(H12,"m","ft") -> 0 | L12: ALTO | M12: =INGRESO_DATOS_SALA!N15 -> 0 | N12: =CONVERT(M12,"m","ft") -> 0 | P12: ALTO | Q12: =INGRESO_DATOS_SALA!R15 -> 0 | R12: =CONVERT(Q12,"m","ft") -> 0
C13: PISO FALSO | D13: =INGRESO_DATOS_SALA!D16 -> 0 | E13: =CONVERT(D13,"m","ft") -> 0 | G13: PISO FALSO | H13: =INGRESO_DATOS_SALA!J16 -> 0 | I13: =CONVERT(H13,"m","ft") -> 0 | L13: PISO FALSO | M13: =INGRESO_DATOS_SALA!N16 -> 0 | N13: =CONVERT(M13,"m","ft") -> 0 | P13: PISO FALSO | Q13: =INGRESO_DATOS_SALA!R16 -> 0 | R13: =CONVERT(Q13,"m","ft") -> 0
C14: CIELO FALSO | D14: =INGRESO_DATOS_SALA!D17 -> 0 | E14: =CONVERT(D14,"m","ft") -> 0 | G14: CIELO FALSO | H14: =INGRESO_DATOS_SALA!J17 -> 0 | I14: =CONVERT(H14,"m","ft") -> 0 | L14: CIELO FALSO | M14: =INGRESO_DATOS_SALA!N17 -> 0 | N14: =CONVERT(M14,"m","ft") -> 0 | P14: CIELO FALSO | Q14: =INGRESO_DATOS_SALA!R17 -> 0 | R14: =CONVERT(Q14,"m","ft") -> 0
C15: ALTO TOTAL | D15: =D12+D13+D14 -> 1 | E15: =CONVERT(D15,"m","ft") -> 3.2808399 | G15: ALTO TOTAL | H15: =SUM(H12:H14) -> 0 | I15: =CONVERT(H15,"m","ft") -> 0 | L15: ALTO TOTAL | M15: =SUM(M12:M14) -> 0 | N15: =CONVERT(M15,"m","ft") -> 0 | P15: ALTO TOTAL | Q15: =SUM(Q12:Q14) -> 0 | R15: =CONVERT(Q15,"m","ft") -> 0
C16: AREA | D16: =D11*D10 -> 1 | E16: =CONVERT(D16,"m","ft") -> 3.2808399 | G16: AREA | H16: =H11*H10 -> 0 | I16: =CONVERT(H16,"m","ft") -> 0 | L16: AREA | M16: =M11*M10 -> 0 | N16: =CONVERT(M16,"m","ft") -> 0 | P16: AREA | Q16: =Q11*Q10 -> 0 | R16: =CONVERT(Q16,"m","ft") -> 0
C17: VOLUMEN | D17: =+D16*D15 -> 1 | E17: =CONVERT(D17,"m","ft") -> 3.2808399 | G17: VOLUMEN | H17: =+H16*H15 -> 0 | I17: =CONVERT(H17,"m","ft") -> 0 | L17: VOLUMEN | M17: =+M16*M15 -> 0 | N17: =CONVERT(M17,"m","ft") -> 0 | P17: VOLUMEN | Q17: =+Q16*Q15 -> 0 | R17: =CONVERT(Q17,"m","ft") -> 0
B20: FM - 200 | L20: NOVEC - 1230 | V20: ECARO - 25
B22: HAZARD INFORMATION | C22: AREA 1 | D22: AREA 2 | E22: AREA 3 | F22: AREA 4 | G22: AREA 5 | H22: AREA 6 | L22: HAZARD INFORMATION | M22: AREA 1 | N22: AREA 2 | O22: AREA 3 | P22: AREA 4 | Q22: AREA 5 | R22: AREA 6 | V22: HAZARD INFORMATION | W22: AREA 1 | X22: AREA 2 | Y22: AREA 3 | Z22: AREA 4 | AA22: AREA 5 | AB22: AREA 6
B23: Area Name: | L23: Area Name: | V23: Area Name:
B24: Length (ft.): | C24: =CALC_AGENT!E10 -> 3.2808399 | D24: =CALC_AGENT!I10 -> 0 | E24: =IF(N10>0,N10,IF(E30>0,E25*2,0)) -> 0 | F24: =IF(R10>0,R10,IF(F30>0,F25*2,0)) -> 0 | L24: Length (ft.): | M24: =IF(E10>0,E10,IF(M30>0,M25*2,0)) -> 3.2808399 | N24: =IF(I10>0,I10,IF(N30>0,N25*2,0)) -> 0 | O24: =IF(N10>0,N10,IF(O30>0,O25*2,0)) -> 0 | P24: =IF(R10>0,R10,IF(P30>0,P25*2,0)) -> 0 | V24: Length (ft.): | W24: =IF(E10>0,E10,IF(W30>0,W25*2,0)) -> 3.2808399 | X24: =IF(I10>0,I10,IF(X30>0,X25*2,0)) -> 0 | Y24: =IF(N10>0,N10,IF(Y30>0,Y25*2,0)) -> 0 | Z24: =IF(R10>0,R10,IF(Z30>0,Z25*2,0)) -> 0
B25: Width (ft.): | C25: =CALC_AGENT!E11 -> 3.2808399 | D25: =CALC_AGENT!I11 -> 0 | E25: =IF(N11>0,N11,IF(E30>0,(E28/2)^0.5,0)) -> 0 | F25: =IF(R11>0,R11,IF(F30>0,(F28/2)^0.5,0)) -> 0 | L25: Width (ft.): | M25: =IF(E11>0,E11,IF(M30>0,(M28/2)^0.5,0)) -> 3.2808399 | N25: =IF(I11>0,I11,IF(N30>0,(N28/2)^0.5,0)) -> 0 | O25: =IF(N11>0,N11,IF(O30>0,(O28/2)^0.5,0)) -> 0 | P25: =IF(R11>0,R11,IF(P30>0,(P28/2)^0.5,0)) -> 0 | V25: Width (ft.): | W25: =IF(E11>0,E11,IF(W30>0,(W28/2)^0.5,0)) -> 3.2808399 | X25: =IF(I11>0,I11,IF(X30>0,(X28/2)^0.5,0)) -> 0 | Y25: =IF(N11>0,N11,IF(Y30>0,(Y28/2)^0.5,0)) -> 0 | Z25: =IF(R11>0,R11,IF(Z30>0,(Z28/2)^0.5,0)) -> 0
B26: Height (ft.): | C26: =CALC_AGENT!E15 -> 3.2808399 | D26: =CALC_AGENT!I15 -> 0 | E26: =IF(N15>0,N15,IF(E30>0,10,0)) -> 0 | F26: =IF(R15>0,R15,IF(F30>0,10,0)) -> 0 | L26: Height (ft.): | M26: =IF(E15>0,E15,IF(M30>0,10,0)) -> 3.2808399 | N26: =IF(I15>0,I15,IF(N30>0,10,0)) -> 0 | O26: =IF(N15>0,N15,IF(O30>0,10,0)) -> 0 | P26: =IF(R15>0,R15,IF(P30>0,10,0)) -> 0 | V26: Height (ft.): | W26: =IF(E15>0,E15,IF(W30>0,10,0)) -> 3.2808399 | X26: =IF(I15>0,I15,IF(X30>0,10,0)) -> 0 | Y26: =IF(N15>0,N15,IF(Y30>0,10,0)) -> 0 | Z26: =IF(R15>0,R15,IF(Z30>0,10,0)) -> 0
B28: Area (sq. ft.): | C28: =IF(C30>0,C30/C26,C24*C25) -> 10.76391 | D28: =IF(D30>0,D30/D26,D24*D25) -> 0 | E28: =IF(E30>0,E30/E26,E24*E25) -> 0 | F28: =IF(F30>0,F30/F26,F24*F25) -> 0 | G28: =IF(G30>0,G30/G26,G24*G25) -> 0 | H28: =IF(H30>0,H30/H26,H24*H25) -> 0 | L28: Area (sq. ft.): | M28: =IF(M30>0,M30/M26,M24*M25) -> 10.76391 | N28: =IF(N30>0,N30/N26,N24*N25) -> 0 | O28: =IF(O30>0,O30/O26,O24*O25) -> 0 | P28: =IF(P30>0,P30/P26,P24*P25) -> 0 | Q28: =IF(Q30>0,Q30/Q26,Q24*Q25) -> 0 | R28: =IF(R30>0,R30/R26,R24*R25) -> 0 | V28: Area (sq. ft.): | W28: =IF(W30>0,W30/W26,W24*W25) -> 10.76391 | X28: =IF(X30>0,X30/X26,X24*X25) -> 0 | Y28: =IF(Y30>0,Y30/Y26,Y24*Y25) -> 0 | Z28: =IF(Z30>0,Z30/Z26,Z24*Z25) -> 0 | AA28: =IF(AA30>0,AA30/AA26,AA24*AA25) -> 0 | AB28: =IF(AB30>0,AB30/AB26,AB24*AB25) -> 0
B29: Volume (cu. ft.): | C29: =C28*C26 -> 35.314667 | D29: =D28*D26 -> 0 | E29: =E28*E26 -> 0 | F29: =F28*F26 -> 0 | G29: =G28*G26 -> 0 | H29: =H28*H26 -> 0 | L29: Volume (cu. ft.): | M29: =M28*M26 -> 35.314667 | N29: =N28*N26 -> 0 | O29: =O28*O26 -> 0 | P29: =P28*P26 -> 0 | Q29: =Q28*Q26 -> 0 | R29: =R28*R26 -> 0 | V29: Volume (cu. ft.): | W29: =W28*W26 -> 35.314667 | X29: =X28*X26 -> 0 | Y29: =Y28*Y26 -> 0 | Z29: =Z28*Z26 -> 0 | AA29: =AA28*AA26 -> 0 | AB29: =AB28*AB26 -> 0
B30: Specified Volume (cu. ft.): | L30: Specified Volume (cu. ft.): | V30: Specified Volume (cu. ft.):
B32: Structural Reductions (cu. ft.): | L32: Structural Reductions (cu. ft.): | V32: Structural Reductions (cu. ft.):
B33: Net Volume: | C33: =C29-C32 -> 35.314667 | D33: =D29-D32 -> 0 | E33: =E29-E32 -> 0 | F33: =F29-F32 -> 0 | G33: =G29-G32 -> 0 | H33: =H29-H32 -> 0 | L33: Net Volume: | M33: =M29-M32 -> 35.314667 | N33: =N29-N32 -> 0 | O33: =O29-O32 -> 0 | P33: =P29-P32 -> 0 | Q33: =Q29-Q32 -> 0 | R33: =R29-R32 -> 0 | V33: Net Volume: | W33: =W29-W32 -> 35.314667 | X33: =X29-X32 -> 0 | Y33: =Y29-Y32 -> 0 | Z33: =Z29-Z32 -> 0 | AA33: =AA29-AA32 -> 0 | AB33: =AB29-AB32 -> 0
B34: DESIGN CONCENTRATION: | C34: ='COT AGENTES'!M13 -> 8.1 | D34: =+C34 -> 8.1 | E34: =+C34 -> 8.1 | F34: =+D34 -> 8.1 | G34: =+E34 -> 8.1 | H34: =+F34 -> 8.1 | L34: DESIGN CONCENTRATION: | M34: ='COT AGENTES'!$M$12 -> 4.52 | N34: ='COT AGENTES'!$M$12 -> 4.52 | O34: ='COT AGENTES'!$M$12 -> 4.52 | P34: ='COT AGENTES'!$M$12 -> 4.52 | Q34: ='COT AGENTES'!$M$12 -> 4.52 | R34: ='COT AGENTES'!$M$12 -> 4.52 | V34: DESIGN CONCENTRATION: | W34: 9.5 | X34: 9.5 | Y34: 9.5 | Z34: 9.5 | AA34: 9.5 | AB34: 9.5
B35: Minimum Ambient Temp.: | C35: =CONVERT('COT AGENTES'!$O$4,"C","F") -> 64.4 | D35: =CONVERT('COT AGENTES'!$O$4,"C","F") -> 64.4 | E35: =CONVERT('COT AGENTES'!$O$4,"C","F") -> 64.4 | F35: =CONVERT('COT AGENTES'!$O$4,"C","F") -> 64.4 | G35: =CONVERT('COT AGENTES'!$O$4,"C","F") -> 64.4 | H35: =CONVERT('COT AGENTES'!$O$4,"C","F") -> 64.4 | L35: Minimum Ambient Temp.: | M35: =CONVERT('COT AGENTES'!$O$4,"C","F") -> 64.4 | N35: =CONVERT('COT AGENTES'!$O$4,"C","F") -> 64.4 | O35: =CONVERT('COT AGENTES'!$O$4,"C","F") -> 64.4 | P35: =CONVERT('COT AGENTES'!$O$4,"C","F") -> 64.4 | Q35: =CONVERT('COT AGENTES'!$O$4,"C","F") -> 64.4 | R35: =CONVERT('COT AGENTES'!$O$4,"C","F") -> 64.4 | V35: Minimum Ambient Temp.: | W35: =IF(W$24>0,65,0) -> 65 | X35: =IF(X$24>0,65,0) -> 0 | Y35: =IF(Y$24>0,65,0) -> 0 | Z35: =IF(Z$24>0,65,0) -> 0 | AA35: =IF(AA$24>0,65,0) -> 0 | AB35: =IF(AB$24>0,65,0) -> 0
B36: Maximum Ambient Temp.: | C36: =CONVERT('COT AGENTES'!$O$6,"C","F") -> 80.6 | D36: =CONVERT('COT AGENTES'!$O$6,"C","F") -> 80.6 | E36: =CONVERT('COT AGENTES'!$O$6,"C","F") -> 80.6 | F36: =CONVERT('COT AGENTES'!$O$6,"C","F") -> 80.6 | G36: =CONVERT('COT AGENTES'!$O$6,"C","F") -> 80.6 | H36: =CONVERT('COT AGENTES'!$O$6,"C","F") -> 80.6 | L36: Maximum Ambient Temp.: | M36: =CONVERT('COT AGENTES'!$O$6,"C","F") -> 80.6 | N36: =CONVERT('COT AGENTES'!$O$6,"C","F") -> 80.6 | O36: =CONVERT('COT AGENTES'!$O$6,"C","F") -> 80.6 | P36: =CONVERT('COT AGENTES'!$O$6,"C","F") -> 80.6 | Q36: =CONVERT('COT AGENTES'!$O$6,"C","F") -> 80.6 | R36: =CONVERT('COT AGENTES'!$O$6,"C","F") -> 80.6 | V36: Maximum Ambient Temp.: | W36: =IF(W$24>0,75,0) -> 75 | X36: =IF(X$24>0,75,0) -> 0 | Y36: =IF(Y$24>0,75,0) -> 0 | Z36: =IF(Z$24>0,75,0) -> 0 | AA36: =IF(AA$24>0,75,0) -> 0 | AB36: =IF(AB$24>0,75,0) -> 0
B37: Normal Ambient Temperature: | C37: =IF(C$24>0,70,0) -> 70 | D37: =IF(D$24>0,70,0) -> 0 | E37: =IF(E$24>0,70,0) -> 0 | F37: =IF(F$24>0,70,0) -> 0 | G37: =IF(G$24>0,70,0) -> 0 | H37: =IF(H$24>0,70,0) -> 0 | L37: Normal Ambient Temperature: | M37: =IF(M$24>0,70,0) -> 70 | N37: =IF(N$24>0,70,0) -> 0 | O37: =IF(O$24>0,70,0) -> 0 | P37: =IF(P$24>0,70,0) -> 0 | Q37: =IF(Q$24>0,70,0) -> 0 | R37: =IF(R$24>0,70,0) -> 0 | V37: Normal Ambient Temperature: | W37: =IF(W$24>0,70,0) -> 70 | X37: =IF(X$24>0,70,0) -> 0 | Y37: =IF(Y$24>0,70,0) -> 0 | Z37: =IF(Z$24>0,70,0) -> 0 | AA37: =IF(AA$24>0,70,0) -> 0 | AB37: =IF(AB$24>0,70,0) -> 0
B39: Altitude Correction: | C39: =CALC_AGENT!$E$7 -> 3.2808399 | D39: =IF(D24>0,$C39,0) -> 0 | E39: =IF(E24>0,$C39,0) -> 0 | F39: =IF(F24>0,$C39,0) -> 0 | G39: =IF(G24>0,$C39,0) -> 0 | H39: =IF(H24>0,$C39,0) -> 0 | L39: Altitude Correction: | M39: =CALC_AGENT!$E$7 -> 3.2808399 | N39: =IF(N24>0,$M39,0) -> 0 | O39: =IF(O24>0,$M39,0) -> 0 | P39: =IF(P24>0,$M39,0) -> 0 | Q39: =IF(Q24>0,$M39,0) -> 0 | R39: =IF(R24>0,$M39,0) -> 0 | V39: Altitude Correction: | W39: =CALC_AGENT!$E$7 -> 3.2808399 | X39: =IF(X24>0,$M39,0) -> 0 | Y39: =IF(Y24>0,$M39,0) -> 0 | Z39: =IF(Z24>0,$M39,0) -> 0 | AA39: =IF(AA24>0,$M39,0) -> 0 | AB39: =IF(AB24>0,$M39,0) -> 0
B42: VOLUME CALCULATIONS: | C42: AREA 1 | D42: AREA 2 | E42: AREA 3 | F42: AREA 4 | G42: AREA 5 | H42: AREA 6 | L42: VOLUME CALCULATIONS: | M42: AREA 1 | N42: AREA 2 | O42: AREA 3 | P42: AREA 4 | Q42: AREA 5 | R42: AREA 6 | V42: VOLUME CALCULATIONS: | W42: AREA 1 | X42: AREA 2 | Y42: AREA 3 | Z42: AREA 4 | AA42: AREA 5 | AB42: AREA 6
B43: Area Name: | C43: =C23 -> 0 | D43: =D23 -> 0 | E43: =E23 -> 0 | F43: =F23 -> 0 | G43: =G23 -> 0 | H43: =H23 -> 0 | L43: Area Name: | M43: =M23 -> 0 | N43: =N23 -> 0 | O43: =O23 -> 0 | P43: =P23 -> 0 | Q43: =Q23 -> 0 | R43: =R23 -> 0 | V43: Area Name: | W43: =W23 -> 0 | X43: =X23 -> 0 | Y43: =Y23 -> 0 | Z43: =Z23 -> 0 | AA43: =AA23 -> 0 | AB43: =AB23 -> 0
B44: Length (ft.): | C44: =C24 -> 3.2808399 | D44: =D24 -> 0 | E44: =E24 -> 0 | F44: =F24 -> 0 | G44: =G24 -> 0 | H44: =H24 -> 0 | L44: Length (ft.): | M44: =M24 -> 3.2808399 | N44: =N24 -> 0 | O44: =O24 -> 0 | P44: =P24 -> 0 | Q44: =Q24 -> 0 | R44: =R24 -> 0 | V44: Length (ft.): | W44: =W24 -> 3.2808399 | X44: =X24 -> 0 | Y44: =Y24 -> 0 | Z44: =Z24 -> 0 | AA44: =AA24 -> 0 | AB44: =AB24 -> 0
B45: Width (ft.): | C45: =C25 -> 3.2808399 | D45: =D25 -> 0 | E45: =E25 -> 0 | F45: =F25 -> 0 | G45: =G25 -> 0 | H45: =H25 -> 0 | L45: Width (ft.): | M45: =M25 -> 3.2808399 | N45: =N25 -> 0 | O45: =O25 -> 0 | P45: =P25 -> 0 | Q45: =Q25 -> 0 | R45: =R25 -> 0 | V45: Width (ft.): | W45: =W25 -> 3.2808399 | X45: =X25 -> 0 | Y45: =Y25 -> 0 | Z45: =Z25 -> 0 | AA45: =AA25 -> 0 | AB45: =AB25 -> 0
B46: Height (ft.): | C46: =C26 -> 3.2808399 | D46: =D26 -> 0 | E46: =E26 -> 0 | F46: =F26 -> 0 | G46: =G26 -> 0 | H46: =H26 -> 0 | L46: Height (ft.): | M46: =M26 -> 3.2808399 | N46: =N26 -> 0 | O46: =O26 -> 0 | P46: =P26 -> 0 | Q46: =Q26 -> 0 | R46: =R26 -> 0 | V46: Height (ft.): | W46: =W26 -> 3.2808399 | X46: =X26 -> 0 | Y46: =Y26 -> 0 | Z46: =Z26 -> 0 | AA46: =AA26 -> 0 | AB46: =AB26 -> 0
B48: Area (sq. ft.): | C48: =C44*C45 -> 10.76391 | D48: =D44*D45 -> 0 | E48: =E44*E45 -> 0 | F48: =F44*F45 -> 0 | G48: =G44*G45 -> 0 | H48: =H44*H45 -> 0 | L48: Area (sq. ft.): | M48: =M44*M45 -> 10.76391 | N48: =N44*N45 -> 0 | O48: =O44*O45 -> 0 | P48: =P44*P45 -> 0 | Q48: =Q44*Q45 -> 0 | R48: =R44*R45 -> 0 | V48: Area (sq. ft.): | W48: =W44*W45 -> 10.76391 | X48: =X44*X45 -> 0 | Y48: =Y44*Y45 -> 0 | Z48: =Z44*Z45 -> 0 | AA48: =AA44*AA45 -> 0 | AB48: =AB44*AB45 -> 0
B49: Volume (cu. ft.): | C49: =C48*C46 -> 35.314667 | D49: =D48*D46 -> 0 | E49: =E48*E46 -> 0 | F49: =F48*F46 -> 0 | G49: =G48*G46 -> 0 | H49: =H48*H46 -> 0 | L49: Volume (cu. ft.): | M49: =M48*M46 -> 35.314667 | N49: =N48*N46 -> 0 | O49: =O48*O46 -> 0 | P49: =P48*P46 -> 0 | Q49: =Q48*Q46 -> 0 | R49: =R48*R46 -> 0 | V49: Volume (cu. ft.): | W49: =W48*W46 -> 35.314667 | X49: =X48*X46 -> 0 | Y49: =Y48*Y46 -> 0 | Z49: =Z48*Z46 -> 0 | AA49: =AA48*AA46 -> 0 | AB49: =AB48*AB46 -> 0
B50: Addtional Volume (air receivers, etc.)(sq. ft.): | L50: Addtional Volume (air receivers, etc.)(sq. ft.): | V50: Addtional Volume (air receivers, etc.)(sq. ft.):
B51: Gross Volume (cu. ft.): | C51: =SUM(C49:C50) -> 35.314667 | D51: =SUM(D49:D50) -> 0 | E51: =SUM(E49:E50) -> 0 | F51: =SUM(F49:F50) -> 0 | G51: =SUM(G49:G50) -> 0 | H51: =SUM(H49:H50) -> 0 | L51: Gross Volume (cu. ft.): | M51: =SUM(M49:M50) -> 35.314667 | N51: =SUM(N49:N50) -> 0 | O51: =SUM(O49:O50) -> 0 | P51: =SUM(P49:P50) -> 0 | Q51: =SUM(Q49:Q50) -> 0 | R51: =SUM(R49:R50) -> 0 | V51: Gross Volume (cu. ft.): | W51: =SUM(W49:W50) -> 35.314667 | X51: =SUM(X49:X50) -> 0 | Y51: =SUM(Y49:Y50) -> 0 | Z51: =SUM(Z49:Z50) -> 0 | AA51: =SUM(AA49:AA50) -> 0 | AB51: =SUM(AB49:AB50) -> 0
B53: Volume Reductions: | L53: Volume Reductions: | V53: Volume Reductions:
B54: Structural Reductions (cu. ft.): | C54: =C32 -> 0 | D54: =D32 -> 0 | E54: =E32 -> 0 | F54: =F32 -> 0 | G54: =G32 -> 0 | H54: =H32 -> 0 | L54: Structural Reductions (cu. ft.): | M54: =M32 -> 0 | N54: =N32 -> 0 | O54: =O32 -> 0 | P54: =P32 -> 0 | Q54: =Q32 -> 0 | R54: =R32 -> 0 | V54: Structural Reductions (cu. ft.): | W54: =W32 -> 0 | X54: =X32 -> 0 | Y54: =Y32 -> 0 | Z54: =Z32 -> 0 | AA54: =AA32 -> 0 | AB54: =AB32 -> 0
...

Sheet INGRESO_DATOS_SALA
C4: ALTURA GEOGRAFICA | D4: METROS (msnm) | E4: PIES | I4: =IF(D5="","INGRESAR ALTURA MSNM",IF(D13="","INGRESAR LARGO",IF(D14="","INGRESAR ANCHO",IF(D15="","INGRESAR ALTO","")))) | P4: Ver cotizacion
D5: =IF('[1]COT AGENTES'!H10=0,"",'[1]COT AGENTES'!H10) -> 1 | E5: =D5*[1]CALC_AGENT!$E$4 -> 3.28083
I8: COMPLETAR SOLO CUANDO SE QUIERE PROTEGER 2 O MAS SALAS CON 1 SISTEMA
C10: SALA 1 | I10: SALA 2 | M10: SALA 3 | Q10: SALA 4
D12: METROS | E12: PIES | J12: METROS | K12: PIES | N12: METROS | O12: PIES | R12: METROS | S12: PIES
C13: LARGO | D13: =IF('[1]COT AGENTES'!M3=0,"",'[1]COT AGENTES'!M3) -> 1 | E13: =D13*[1]CALC_AGENT!$E$4 -> 3.28083 | I13: LARGO | K13: =J13*[1]CALC_AGENT!$E$4 -> 0 | M13: LARGO | O13: =N13*[1]CALC_AGENT!$E$4 -> 0 | Q13: LARGO | S13: =R13*[1]CALC_AGENT!$E$4 -> 0
C14: ANCHO | D14: =IF('[1]COT AGENTES'!M4=0,"",'[1]COT AGENTES'!M4) -> 1 | E14: =D14*[1]CALC_AGENT!$E$4 -> 3.28083 | I14: ANCHO | K14: =J14*[1]CALC_AGENT!$E$4 -> 0 | M14: ANCHO | O14: =N14*[1]CALC_AGENT!$E$4 -> 0 | Q14: ANCHO | S14: =R14*[1]CALC_AGENT!$E$4 -> 0
C15: ALTO | D15: =IF('[1]COT AGENTES'!M5=0,"0",'[1]COT AGENTES'!M5) -> 1 | E15: =D15*[1]CALC_AGENT!$E$4 -> 3.28083 | I15: ALTO | K15: =J15*[1]CALC_AGENT!$E$4 -> 0 | M15: ALTO | O15: =N15*[1]CALC_AGENT!$E$4 -> 0 | Q15: ALTO | S15: =R15*[1]CALC_AGENT!$E$4 -> 0
C16: PISO FALSO | D16: =IF('[1]COT AGENTES'!M6=0,"0",'[1]COT AGENTES'!M6) -> 0 | E16: =D16*[1]CALC_AGENT!$E$4 -> 0 | I16: PISO FALSO | K16: =J16*[1]CALC_AGENT!$E$4 -> 0 | M16: PISO FALSO | O16: =N16*[1]CALC_AGENT!$E$4 -> 0 | Q16: PISO FALSO | S16: =R16*[1]CALC_AGENT!$E$4 -> 0
C17: CIELO FALSO | D17: =IF('[1]COT AGENTES'!M7=0,"0",'[1]COT AGENTES'!M7) -> 0 | E17: =D17*[1]CALC_AGENT!$E$4 -> 0 | I17: CIELO FALSO | K17: =J17*[1]CALC_AGENT!$E$4 -> 0 | M17: CIELO FALSO | O17: =N17*[1]CALC_AGENT!$E$4 -> 0 | Q17: CIELO FALSO | S17: =R17*[1]CALC_AGENT!$E$4 -> 0
C18: ALTO TOTAL | D18: =SUM(D15:D17) -> 1 | E18: =D18*[1]CALC_AGENT!$E$4 -> 3.28083 | I18: ALTO TOTAL | J18: =SUM(J15:J17) -> 0 | K18: =J18*[1]CALC_AGENT!$E$4 -> 0 | M18: ALTO TOTAL | N18: =SUM(N15:N17) -> 0 | O18: =N18*[1]CALC_AGENT!$E$4 -> 0 | Q18: ALTO TOTAL | R18: =SUM(R15:R17) -> 0 | S18: =R18*[1]CALC_AGENT!$E$4 -> 0
C19: AREA | D19: =D14*D13 -> 1 | E19: =D19*[1]CALC_AGENT!$E$4 -> 3.28083 | I19: AREA | J19: =J14*J13 -> 0 | K19: =J19*[1]CALC_AGENT!$E$4 -> 0 | M19: AREA | N19: =N14*N13 -> 0 | O19: =N19*[1]CALC_AGENT!$E$4 -> 0 | Q19: AREA | R19: =R14*R13 -> 0 | S19: =R19*[1]CALC_AGENT!$E$4 -> 0
C20: VOLUMEN | D20: =+D19*D18 -> 1 | E20: =D20*[1]CALC_AGENT!$E$4 -> 3.28083 | I20: VOLUMEN | J20: =+J19*J18 -> 0 | K20: =J20*[1]CALC_AGENT!$E$4 -> 0 | M20: VOLUMEN | N20: =+N19*N18 -> 0 | O20: =N20*[1]CALC_AGENT!$E$4 -> 0 | Q20: VOLUMEN | R20: =+R19*R18 -> 0 | S20: =R20*[1]CALC_AGENT!$E$4 -> 0
C21: Nozzle | D21: =IF(D19>0,ROUNDUP((IF(D13<8,8,D13)*IF(D14<8,8,D14))/90,0),0) -> 1 | I21: Nozzle | J21: =IF(J19>0,ROUNDUP((IF(J13<8,8,J13)*IF(J14<8,8,J14))/90,0),0) -> 0 | M21: Nozzle | N21: =IF(N19>0,ROUNDUP((IF(N13<8,8,N13)*IF(N14<8,8,N14))/90,0),0) -> 0 | Q21: Nozzle | R21: =IF(R19>0,ROUNDUP((IF(R13<8,8,R13)*IF(R14<8,8,R14))/90,0),0) -> 0
I25: =IF(D19>0,ROUNDUP((IF(D13<8,8,D13)*IF(D14<8,8,D14))/64,0),0) -> 1

Sheet BDD_SISTEMAS- MANIFOLD
A1: id | B1: KEY | C1: IN | D1: TIPO | E1: CILINDRO | F1: AGENTE | G1: Ítem | H1: Marca | I1: Codigo | J1: Producto | K1: U/M | L1: Cant. | M1: Entrega | N1: Precio
A2: 1 | B2: =D2&E2&F2&C2&"-"&G2&IF(M2<>"",O2,"") -> SISTEMATANK SIZE 8LFM-2001-1 | C2: =L2 -> 1 | D2: SISTEMA | E2: TANK SIZE 8L | F2: FM-200 | G2: 1 | H2: ANSUL | I2: AGLIMP-RECARGA-00 | J2: SERVICIO DE CARGA DE AGENTE 8L | K2: c/u. | L2: 1 | M2: 8L CARGA | N2: 1
A3: 2 | B3: =D3&E3&F3&C3&"-"&G3&IF(M3<>"",O3,"") -> SISTEMATANK SIZE 8LFM-2001-2 | C3: =C2 -> 1 | D3: SISTEMA | E3: TANK SIZE 8L | F3: FM-200 | G3: =+G2+1 -> 2 | H3: ANSUL | I3: 445732 | J3: TANK SIZE 8L, Fill: 9-17 lb. | K3: c/u. | L3: 1 | M3: =I3 -> 445732 | N3: 1
A4: 3 | B4: =D4&E4&F4&C4&"-"&G4&IF(M4<>"",O4,"") -> SISTEMATANK SIZE 8LFM-2001-3 | C4: =C3 -> 1 | D4: SISTEMA | E4: TANK SIZE 8L | F4: FM-200 | G4: =+G3+1 -> 3 | H4: ANSUL | I4: FM-200-SRL | J4: FM-200 Agent, | K4: c/u. | L4: ='COT AGENTES'!$H$5 -> 2 | M4: 453646 | N4: 1
A5: 4 | B5: =D5&E5&F5&C5&"-"&G5&IF(M5<>"",O5,"") -> SISTEMATANK SIZE 8LFM-2001-4 | C5: =C4 -> 1 | D5: SISTEMA | E5: TANK SIZE 8L | F5: FM-200 | G5: =+G4+1 -> 4 | H5: ANSUL | I5: 570055 | J5: Gauge, Cylinder Valve FM-200 | K5: c/u. | L5: =L3 -> 1 | M5: =I5 -> 570055 | N5: 1
A6: 5 | B6: =D6&E6&F6&C6&"-"&G6&IF(M6<>"",O6,"") -> SISTEMATANK SIZE 8LFM-2001-5 | C6: =C5 -> 1 | D6: SISTEMA | E6: TANK SIZE 8L | F6: FM-200 | G6: =+G5+1 -> 5 | H6: ANSUL | I6: 314205321 | J6: Label FM-200 8/16/52L UL/FM | K6: c/u. | L6: =L3 -> 1 | M6: =I6 -> 314205321 | N6: 1
A7: 6 | B7: =D7&E7&F7&C7&"-"&G7&IF(M7<>"",O7,"") -> SISTEMATANK SIZE 8LFM-2001-6 | C7: =C6 -> 1 | D7: SISTEMA | E7: TANK SIZE 8L | F7: FM-200 | G7: =+G6+1 -> 6 | H7: ANSUL | I7: 570585 | J7: Cylinder Low Pressure Switch | K7: c/u. | L7: 1 | M7: =I7 -> 570585 | N7: 1
A8: 7 | B8: =D8&E8&F8&C8&"-"&G8&IF(M8<>"",O8,"") -> SISTEMATANK SIZE 8LFM-2001-7 | C8: =C7 -> 1 | D8: SISTEMA | E8: TANK SIZE 8L | F8: FM-200 | G8: =+G7+1 -> 7 | H8: ANSUL | I8: 304205030 | J8: Electric Actuator Shipping Assembly | K8: c/u. | L8: 1 | M8: =I8 -> 304205030 | N8: 1
A9: 8 | B9: =D9&E9&F9&C9&"-"&G9&IF(M9<>"",O9,"") -> SISTEMATANK SIZE 8LFM-2001-8 | C9: =C8 -> 1 | D9: SISTEMA | E9: TANK SIZE 8L | F9: FM-200 | G9: =+G8+1 -> 8 | H9: ANSUL | I9: A1638150HY | J9: Local Manual Actuator | K9: c/u. | L9: 1 | M9: =I9 -> A1638150HY | N9: 1
A10: 9 | B10: =D10&E10&F10&C10&"-"&G10&IF(M10<>"",O10,"") -> SISTEMATANK SIZE 8LFM-2001-9 | C10: =C9 -> 1 | D10: SISTEMA | E10: TANK SIZE 8L | F10: FM-200 | G10: =+G9+1 -> 9 | H10: ANSUL | I10: 570085-R2 | J10: Tank Bracket Assembly (Fits 20, 50 & 90 lb. Tanks) | K10: c/u. | L10: 1 | M10: =I10 -> 570085-R2 | N10: 1
A11: 10 | B11: =D11&E11&F11&C11&"-"&G11&IF(M11<>"",O11,"") -> SISTEMATANK SIZE 8LFM-2001-10 | C11: =C10 -> 1 | D11: SISTEMA | E11: TANK SIZE 8L | F11: FM-200 | G11: =+G10+1 -> 10 | H11: ANSUL | I11: 17549OK | J11: Nozzle, según memoria de calculo | K11: c/u. | L11: ='COT AGENTES'!$M$11 -> 1 | M11: NOZ. 8L | N11: 1
A12: 11 | B12: =D12&E12&F12&C12&"-"&G12&IF(M12<>"",O12,"") -> SISTEMATANK SIZE 8LFM-2001-11 | C12: =C11 -> 1 | D12: SISTEMA | E12: TANK SIZE 8L | F12: FM-200 | G12: =+G11+1 -> 11 | H12: ANSUL | I12: 442927-R2 | J12: NAMEPLATE, FM200, DO NOT ENTER | K12: c/u. | L12: 1 | M12: =I12 -> 442927-R2 | N12: 1
A13: 12 | B13: =D13&E13&F13&C13&"-"&G13&IF(M13<>"",O13,"") -> SISTEMATANK SIZE 8LFM-2001-12 | C13: =C12 -> 1 | D13: SISTEMA | E13: TANK SIZE 8L | F13: FM-200 | G13: =+G12+1 -> 12 | H13: ANSUL | I13: 442928-R2 | J13: NAMEPLATE, FM200, PROTECTED, | K13: c/u. | L13: 1 | M13: =I13 -> 442928-R2 | N13: 1
A14: 13 | B14: =D14&E14&F14&C14&"-"&G14&IF(M14<>"",O14,"") -> SISTEMATANK SIZE 8LFM-2001-13 | C14: =C13 -> 1 | D14: SISTEMA | E14: TANK SIZE 8L | F14: FM-200 | G14: =+G13+1 -> 13 | H14: ANSUL | I14: 570557 | J14: Single-Tank Swivel Adaptor, 1 in. (P/N 309002016) | K14: c/u. | L14: =L3 -> 1 | M14: =I14 -> 570557 | N14: 1
A15: 14 | B15: =D15&E15&F15&C15&"-"&G15&IF(M15<>"",O15,"") -> SISTEMATANK SIZE 8LFM-2001-14 | C15: =C14 -> 1 | D15: SISTEMA | E15: TANK SIZE 8L | F15: FM-200 | G15: =+G14+1 -> 14 | K15: c/u. | M15: =I15 -> 0 | N15: 1
A16: 15 | B16: =D16&E16&F16&C16&"-"&G16&IF(M16<>"",O16,"") -> SISTEMATANK SIZE 8LFM-2001-15 | C16: =C15 -> 1 | D16: SISTEMA | E16: TANK SIZE 8L | F16: FM-200 | G16: =+G15+1 -> 15 | H16: ANSUL | I16: 437900 | J16: Switch, Pressure, 3PDT | K16: c/u. | L16: 1 | M16: =I16 -> 437900 | N16: 1
A17: 16 | B17: =D17&E17&F17&C17&"-"&G17&IF(M17<>"",O17,"") -> SISTEMATANK SIZE 8LFM-2001-16 | C17: =C16 -> 1 | D17: SISTEMA | E17: TANK SIZE 8L | F17: FM-200 | G17: =+G16+1 -> 16 | H17: ANSUL | I17: 73597 | J17: Acutation Hose, 16 in., 1/4 in. NPT x 7/16-20 in. F Flare | K17: c/u. | L17: 1 | M17: =I17 -> 73597 | N17: 1
A18: 17 | B18: =D18&E18&F18&C18&"-"&G18&IF(M18<>"",O18,"") -> SISTEMATANK SIZE 8LFM-2001-17 | C18: =C17 -> 1 | D18: SISTEMA | E18: TANK SIZE 8L | F18: FM-200 | G18: =+G17+1 -> 17 | H18: ANSUL | I18: 32338 | J18: Male Straight Connector, 7/16 - 20 x 1/4 in. NPT | K18: c/u. | L18: 1 | M18: =I18 -> 32338 | N18: 1
A19: 18 | B19: =D19&E19&F19&C19&"-"&G19&IF(M19<>"",O19,"") -> - | M19: =I19 -> 0 | N19: 1
A20: 19 | B20: =D20&E20&F20&C20&"-"&G20&IF(M20<>"",O20,"") -> OPCIONALTANK SIZE 8LFM-2001-1 | C20: =C13 -> 1 | D20: OPCIONAL | E20: TANK SIZE 8L | F20: FM-200 | G20: 1 | H20: ANSUL | I20: 570539-R2 | J20: Flexible Discharge Hose, 1 in. | K20: c/u. | L20: =L3 -> 1 | M20: =I20 -> 570539-R2 | N20: 1
A21: 20 | B21: =D21&E21&F21&C21&"-"&G21&IF(M21<>"",O21,"") -> OPCIONALTANK SIZE 8LFM-2001-2 | C21: =C20 -> 1 | D21: OPCIONAL | E21: TANK SIZE 8L | F21: FM-200 | G21: =+G20+1 -> 2 | H21: ANSUL | I21: 437900 | J21: Switch, Pressure, 3PDT | K21: c/u. | L21: 1 | M21: =I21 -> 437900 | N21: 1
A22: 21 | B22: =D22&E22&F22&C22&"-"&G22&IF(M22<>"",O22,"") -> OPCIONALTANK SIZE 8LFM-2001-3 | C22: =C20 -> 1 | D22: OPCIONAL | E22: TANK SIZE 8L | F22: FM-200 | G22: =+G21+1 -> 3 | H22: ANSUL | I22: 73597 | J22: Acutation Hose, 16 in., 1/4 in. NPT x 7/16-20 in. F Flare | K22: c/u. | L22: 1 | M22: =I22 -> 73597 | N22: 1
A23: 22 | B23: =D23&E23&F23&C23&"-"&G23&IF(M23<>"",O23,"") -> OPCIONALTANK SIZE 8LFM-2001-4 | C23: =C20 -> 1 | D23: OPCIONAL | E23: TANK SIZE 8L | F23: FM-200 | G23: =+G22+1 -> 4 | H23: ANSUL | I23: 32338 | J23: Male Straight Connector, 7/16 - 20 x 1/4 in. NPT | K23: c/u. | L23: 1 | M23: =I23 -> 32338 | N23: 1
A24: 23 | B24: =D24&E24&F24&C24&"-"&G24&IF(M24<>"",O24,"") -> OPCIONALTANK SIZE 8LFM-2001-5 | C24: =C23 -> 1 | D24: OPCIONAL | E24: TANK SIZE 8L | F24: FM-200 | G24: =+G23+1 -> 5 | H24: ANSUL | I24: 76498 | J24: Switch, Maintenance, Surface Mount | K24: c/u. | L24: 1 | M24: =I24 -> 76498 | N24: 1
A25: 24 | B25: =D25&E25&F25&C25&"-"&G25&IF(M25<>"",O25,"") -> - | M25: =I25 -> 0 | N25: 1
A26: 25 | B26: =D26&E26&F26&C26&"-"&G26&IF(M26<>"",O26,"") -> SISTEMATANK SIZE 16LFM-2001-1 | C26: =L26 -> 1 | D26: SISTEMA | E26: TANK SIZE 16L | F26: FM-200 | G26: 1 | H26: ANSUL | I26: AGLIMP-RECARGA-00 | J26: SERVICIO DE CARGA DE AGENTE 16L | K26: c/u. | L26: 1 | M26: 16L CARGA | N26: 1
A27: 26 | B27: =D27&E27&F27&C27&"-"&G27&IF(M27<>"",O27,"") -> SISTEMATANK SIZE 16LFM-2001-2 | C27: =C26 -> 1 | D27: SISTEMA | E27: TANK SIZE 16L | F27: FM-200 | G27: =+G26+1 -> 2 | H27: ANSUL | I27: 445733 | J27: TANK SIZE 16L, Fill: 18-35 lb. | K27: c/u. | L27: 1 | M27: =I27 -> 445733 | N27: 1
A28: 27 | B28: =D28&E28&F28&C28&"-"&G28&IF(M28<>"",O28,"") -> SISTEMATANK SIZE 16LFM-2001-3 | C28: =C27 -> 1 | D28: SISTEMA | E28: TANK SIZE 16L | F28: FM-200 | G28: =+G27+1 -> 3 | H28: ANSUL | I28: FM-200-SRL | J28: FM-200 Agent, | K28: c/u. | L28: ='COT AGENTES'!$H$5 -> 2 | M28: 453646 | N28: 1
A29: 28 | B29: =D29&E29&F29&C29&"-"&G29&IF(M29<>"",O29,"") -> SISTEMATANK SIZE 16LFM-2001-4 | C29: =C28 -> 1 | D29: SISTEMA | E29: TANK SIZE 16L | F29: FM-200 | G29: =+G28+1 -> 4 | H29: ANSUL | I29: 570055 | J29: Gauge, Cylinder Valve FM-200 | K29: c/u. | L29: 1 | M29: =I29 -> 570055 | N29: 1
A30: 29 | B30: =D30&E30&F30&C30&"-"&G30&IF(M30<>"",O30,"") -> SISTEMATANK SIZE 16LFM-2001-5 | C30: =C29 -> 1 | D30: SISTEMA | E30: TANK SIZE 16L | F30: FM-200 | G30: =+G29+1 -> 5 | H30: ANSUL | I30: 314205321 | J30: Label FM-200 8/16/52L UL/FM | K30: c/u. | L30: 1 | M30: =I30 -> 314205321 | N30: 1
A31: 30 | B31: =D31&E31&F31&C31&"-"&G31&IF(M31<>"",O31,"") -> SISTEMATANK SIZE 16LFM-2001-6 | C31: =C30 -> 1 | D31: SISTEMA | E31: TANK SIZE 16L | F31: FM-200 | G31: =+G30+1 -> 6 | H31: ANSUL | I31: 570585 | J31: Cylinder Low Pressure Switch | K31: c/u. | L31: 1 | M31: =I31 -> 570585 | N31: 1
A32: 31 | B32: =D32&E32&F32&C32&"-"&G32&IF(M32<>"",O32,"") -> SISTEMATANK SIZE 16LFM-2001-7 | C32: =C31 -> 1 | D32: SISTEMA | E32: TANK SIZE 16L | F32: FM-200 | G32: =+G31+1 -> 7 | H32: ANSUL | I32: 304205030 | J32: Electric Actuator Shipping Assembly | K32: c/u. | L32: 1 | M32: =I32 -> 304205030 | N32: 1
A33: 32 | B33: =D33&E33&F33&C33&"-"&G33&IF(M33<>"",O33,"") -> SISTEMATANK SIZE 16LFM-2001-8 | C33: =C32 -> 1 | D33: SISTEMA | E33: TANK SIZE 16L | F33: FM-200 | G33: =+G32+1 -> 8 | H33: ANSUL | I33: A1638150HY | J33: Local Manual Actuator | K33: c/u. | L33: 1 | M33: =I33 -> A1638150HY | N33: 1
A34: 33 | B34: =D34&E34&F34&C34&"-"&G34&IF(M34<>"",O34,"") -> SISTEMATANK SIZE 16LFM-2001-9 | C34: =C33 -> 1 | D34: SISTEMA | E34: TANK SIZE 16L | F34: FM-200 | G34: =+G33+1 -> 9 | H34: ANSUL | I34: 570085-R2 | J34: Tank Bracket Assembly (Fits 20, 50 & 90 lb. Tanks) | K34: c/u. | L34: 2 | M34: =I34 -> 570085-R2 | N34: 1
A35: 34 | B35: =D35&E35&F35&C35&"-"&G35&IF(M35<>"",O35,"") -> SISTEMATANK SIZE 16LFM-2001-10 | C35: =C34 -> 1 | D35: SISTEMA | E35: TANK SIZE 16L | F35: FM-200 | G35: =+G34+1 -> 10 | H35: ANSUL | I35: 17549OK | J35: Nozzle, según memoria de calculo | K35: c/u. | L35: ='COT AGENTES'!$M$11 -> 1 | M35: NOZ. 16L | N35: 1
A36: 35 | B36: =D36&E36&F36&C36&"-"&G36&IF(M36<>"",O36,"") -> SISTEMATANK SIZE 16LFM-2001-11 | C36: =C35 -> 1 | D36: SISTEMA | E36: TANK SIZE 16L | F36: FM-200 | G36: =+G35+1 -> 11 | H36: ANSUL | I36: 442927-R2 | J36: NAMEPLATE, FM200, DO NOT ENTER | K36: c/u. | L36: 1 | M36: =I36 -> 442927-R2 | N36: 1
A37: 36 | B37: =D37&E37&F37&C37&"-"&G37&IF(M37<>"",O37,"") -> SISTEMATANK SIZE 16LFM-2001-12 | C37: =C36 -> 1 | D37: SISTEMA | E37: TANK SIZE 16L | F37: FM-200 | G37: =+G36+1 -> 12 | H37: ANSUL | I37: 442928-R2 | J37: NAMEPLATE, FM200, PROTECTED, | K37: c/u. | L37: 1 | M37: =I37 -> 442928-R2 | N37: 1
A38: 37 | B38: =D38&E38&F38&C38&"-"&G38&IF(M38<>"",O38,"") -> SISTEMATANK SIZE 16LFM-2001-13 | C38: =C37 -> 1 | D38: SISTEMA | E38: TANK SIZE 16L | F38: FM-200 | G38: =+G37+1 -> 13 | H38: ANSUL | I38: 570557 | J38: Single-Tank Swivel Adaptor, 1 in. (P/N 309002016) | K38: c/u. | L38: =L27 -> 1 | M38: =I38 -> 570557 | N38: 1
A39: 38 | B39: =D39&E39&F39&C39&"-"&G39&IF(M39<>"",O39,"") -> SISTEMATANK SIZE 16LFM-2001-14 | C39: =C38 -> 1 | D39: SISTEMA | E39: TANK SIZE 16L | F39: FM-200 | G39: =+G38+1 -> 14 | M39: =I39 -> 0 | N39: 1
A40: 39 | B40: =D40&E40&F40&C40&"-"&G40&IF(M40<>"",O40,"") -> SISTEMATANK SIZE 16LFM-2001-15 | C40: =C39 -> 1 | D40: SISTEMA | E40: TANK SIZE 16L | F40: FM-200 | G40: =+G39+1 -> 15 | H40: ANSUL | I40: 437900 | J40: Switch, Pressure, 3PDT | K40: c/u. | L40: 1 | M40: =I40 -> 437900 | N40: 1
...

Sheet tabla_temperatura
B1: tabla temp FM | U1: Vapor Volume S (ft3 / lb)
A2: key | B2: T (ºF) | D2: 6.7 | E2: 7 | F2: 7.17 | G2: 7.2 | H2: 8 | I2: 8.1 | J2: 8.97 | K2: 9 | L2: 10 | M2: 11 | N2: 12 | P2: 6.7 | Q2: 4 | S2: key | T2: T (ºF) | U2: (ft3/lb) | V2: 4.2 | W2: 4.5 | X2: 4.52 | Y2: 4.6 | Z2: 4.7 | AA2: 5 | AB2: 5.5 | AC2: 5.85 | AD2: 6 | AE2: 6.5 | AF2: 7 | AG2: 7.5 | AH2: 8 | AI2: 8.5 | AJ2: 9 | AK2: 9.5 | AL2: 10 | AM2: 13.3 | AN2: 4.2 | AO2: 4
A3: =IF(AND(CALC_AGENT!$C$35<B4,CALC_AGENT!$C$35>=B3),1,0) -> 0 | B3: 10 | C3: 1.931 | D3: 0.0372 | E3: 0.039 | F3: 0.04 | G3: 0.0402 | H3: 0.45 | I3: 0.0456 | J3: 0.051 | K3: 0.0512 | L3: 0.0575 | M3: 0.064 | N3: 0.0706 | P3: 7 | Q3: =+Q2+1 -> 5 | S3: =IF(AND(CALC_AGENT!$C$35<T4,CALC_AGENT!$C$35>=T3),1,0) -> 0 | T3: -20 | U3: 0.9368 | V3: 0.0468 | W3: 0.0503 | X3: 0.050536 | Y3: =((AA3-W3)/5)+W3 -> 0.05148 | Z3: =((AA3-Y3)/4)+Y3 -> 0.05266 | AA3: 0.0562 | AB3: 0.0621 | AC3: 0.0663 | AD3: 0.0681 | AE3: 0.0742 | AF3: 0.0803 | AG3: 0.0866 | AH3: 0.0928 | AI3: 0.0992 | AJ3: 0.1056 | AK3: 0.1121 | AL3: 0.1186 | AM3: 0.1638 | AN3: 4.5 | AO3: =+AO2+1 -> 5
A4: =IF(AND(CALC_AGENT!$C$35<B5,CALC_AGENT!$C$35>=B4),1,0) -> 0 | B4: 20 | C4: 1.977 | D4: 0.0363 | E4: 0.0381 | F4: 0.0391 | G4: 0.0392 | H4: 0.044 | I4: 0.0446 | J4: 0.0498 | K4: 0.05 | L4: 0.0562 | M4: 0.0625 | N4: 0.069 | P4: 7.17 | Q4: =+Q3+1 -> 6 | S4: =IF(AND(CALC_AGENT!$C$35<T5,CALC_AGENT!$C$35>=T4),1,0) -> 0 | T4: -10 | U4: 0.9612 | V4: 0.0456 | W4: 0.049 | X4: 0.049236 | Y4: =((AA4-W4)/5)+W4 -> 0.05016 | Z4: =((AA4-Y4)/4)+Y4 -> 0.05132 | AA4: 0.0548 | AB4: 0.0606 | AC4: 0.0646 | AD4: 0.0664 | AE4: 0.0723 | AF4: 0.0783 | AG4: 0.0844 | AH4: 0.0905 | AI4: 0.0966 | AJ4: 0.1029 | AK4: 0.1092 | AL4: 0.1156 | AM4: 0.1596 | AN4: 4.52 | AO4: 6
A5: =IF(AND(CALC_AGENT!$C$35<B6,CALC_AGENT!$C$35>=B5),1,0) -> 0 | B5: 30 | C5: 2.23 | D5: 0.0355 | E5: 0.0372 | F5: 0.0382 | G5: 0.0384 | H5: 0.043 | I5: 0.0436 | J5: 0.0487 | K5: 0.0489 | L5: 0.0549 | M5: 0.0611 | N5: 0.0674 | P5: 7.2 | Q5: =+Q4+1 -> 7 | S5: =IF(AND(CALC_AGENT!$C$35<T6,CALC_AGENT!$C$35>=T5),1,0) -> 0 | T5: 0 | U5: 0.9856 | V5: 0.0445 | W5: 0.0478 | X5: 0.048036 | Y5: =((AA5-W5)/5)+W5 -> 0.04892 | Z5: =((AA5-Y5)/4)+Y5 -> 0.05004 | AA5: 0.0534 | AB5: 0.0591 | AC5: 0.063 | AD5: 0.0648 | AE5: 0.0705 | AF5: 0.0764 | AG5: 0.0823 | AH5: 0.0882 | AI5: 0.0943 | AJ5: 0.1003 | AK5: 0.1065 | AL5: 0.1127 | AM5: 0.1557 | AN5: 4.6 | AO5: 7
A6: =IF(AND(CALC_AGENT!$C$35<B7,CALC_AGENT!$C$35>=B6),1,0) -> 0 | B6: 40 | C6: 2.069 | D6: 0.0347 | E6: 0.0364 | F6: 0.0373 | G6: 0.0375 | H6: 0.042 | I6: 0.0426 | J6: 0.0476 | K6: 0.0478 | L6: 0.0537 | M6: 0.0597 | N6: 0.0659 | P6: 8 | Q6: =+Q5+1 -> 8 | S6: =IF(AND(CALC_AGENT!$C$35<T7,CALC_AGENT!$C$35>=T6),1,0) -> 0 | T6: 10 | U6: 1.01 | V6: 0.0434 | W6: 0.0467 | X6: 0.046936 | Y6: =((AA6-W6)/5)+W6 -> 0.04778 | Z6: =((AA6-Y6)/4)+Y6 -> 0.04886 | AA6: 0.0521 | AB6: 0.0576 | AC6: 0.0615 | AD6: 0.0632 | AE6: 0.0688 | AF6: 0.0745 | AG6: 0.0803 | AH6: 0.0861 | AI6: 0.092 | AJ6: 0.0979 | AK6: 0.1039 | AL6: 0.11 | AM6: 0.1519 | AN6: 4.7 | AO6: 8
A7: =IF(AND(CALC_AGENT!$C$35<B8,CALC_AGENT!$C$35>=B7),1,0) -> 0 | B7: 50 | C7: 2.115 | D7: 0.034 | E7: 0.0356 | F7: 0.0365 | G7: 0.0367 | H7: 0.0411 | I7: 0.0417 | J7: 0.0466 | K7: 0.0468 | L7: 0.0525 | M7: 0.0584 | N7: 0.0645 | P7: 8.1 | Q7: =+Q6+1 -> 9 | S7: =IF(AND(CALC_AGENT!$C$35<T8,CALC_AGENT!$C$35>=T7),1,0) -> 0 | T7: 20 | U7: 1.0344 | V7: 0.0424 | W7: 0.0456 | X7: 0.045836 | Y7: =((AA7-W7)/5)+W7 -> 0.04666 | Z7: =((AA7-Y7)/4)+Y7 -> 0.04772 | AA7: 0.0509 | AB7: 0.0563 | AC7: 0.0601 | AD7: 0.0617 | AE7: 0.0672 | AF7: 0.0728 | AG7: 0.0784 | AH7: 0.0841 | AI7: 0.0898 | AJ7: 0.0956 | AK7: 0.1015 | AL7: 0.1074 | AM7: 0.1483 | AN7: 5 | AO7: 9
A8: =IF(AND(CALC_AGENT!$C$35<B9,CALC_AGENT!$C$35>=B8),1,0) -> 1 | B8: 60 | C8: 2.161 | D8: 0.0332 | E8: 0.0348 | F8: 0.0357 | G8: 0.0359 | H8: 0.0402 | I8: 0.0408 | J8: 0.0456 | K8: 0.0458 | L8: 0.0514 | M8: 0.0572 | N8: 0.0631 | P8: 8.97 | Q8: =+Q7+1 -> 10 | S8: =IF(AND(CALC_AGENT!$C$35<T9,CALC_AGENT!$C$35>=T8),1,0) -> 0 | T8: 30 | U8: 1.0588 | V8: 0.0414 | W8: 0.0445 | X8: 0.044736 | Y8: =((AA8-W8)/5)+W8 -> 0.04554 | Z8: =((AA8-Y8)/4)+Y8 -> 0.04658 | AA8: 0.0497 | AB8: 0.055 | AC8: 0.0587 | AD8: 0.0603 | AE8: 0.0657 | AF8: 0.0711 | AG8: 0.0766 | AH8: 0.0821 | AI8: 0.0877 | AJ8: 0.0934 | AK8: 0.0991 | AL8: 0.1049 | AM8: 0.1449 | AN8: 5.5 | AO8: 10
A9: =IF(AND(CALC_AGENT!$C$35<B10,CALC_AGENT!$C$35>=B9),1,0) -> 0 | B9: 70 | C9: 2.207 | D9: 0.0325 | E9: 0.0341 | F9: 0.035 | G9: 0.0352 | H9: 0.0394 | I9: 0.0399 | J9: 0.0446 | K9: 0.0448 | L9: 0.0503 | M9: 0.056 | N9: 0.0618 | P9: 9 | Q9: =+Q8+1 -> 11 | S9: =IF(AND(CALC_AGENT!$C$35<T10,CALC_AGENT!$C$35>=T9),1,0) -> 0 | T9: 40 | U9: 1.0832 | V9: 0.0405 | W9: 0.0435 | X9: 0.043736 | Y9: =((AA9-W9)/5)+W9 -> 0.04452 | Z9: =((AA9-Y9)/4)+Y9 -> 0.04554 | AA9: 0.0486 | AB9: 0.0537 | AC9: 0.0574 | AD9: 0.0589 | AE9: 0.0642 | AF9: 0.0695 | AG9: 0.0749 | AH9: 0.0803 | AI9: 0.0858 | AJ9: 0.0913 | AK9: 0.0969 | AL9: 0.1026 | AM9: 0.1417 | AN9: 5.85 | AO9: 11
A10: =IF(AND(CALC_AGENT!$C$35<B11,CALC_AGENT!$C$35>=B10),1,0) -> 0 | B10: 80 | C10: 2.253 | D10: 0.0319 | E10: 0.0334 | F10: 0.0343 | G10: 0.0344 | H10: 0.0386 | I10: 0.0391 | J10: 0.0437 | K10: 0.0439 | L10: 0.0493 | M10: 0.0549 | N10: 0.0605 | P10: 10 | Q10: =+Q9+1 -> 12 | S10: =IF(AND(CALC_AGENT!$C$35<T11,CALC_AGENT!$C$35>=T10),1,0) -> 0 | T10: 50 | U10: 1.0177 | V10: 0.0396 | W10: 0.0425 | X10: 0.042736 | Y10: =((AA10-W10)/5)+W10 -> 0.0435 | Z10: =((AA10-Y10)/4)+Y10 -> 0.0445 | AA10: 0.0475 | AB10: 0.0525 | AC10: 0.0561 | AD10: 0.0576 | AE10: 0.0628 | AF10: 0.068 | AG10: 0.0732 | AH10: 0.0785 | AI10: 0.0839 | AJ10: 0.0893 | AK10: 0.0948 | AL10: 0.1003 | AM10: 0.1385 | AN10: 6 | AO10: 12
A11: =IF(AND(CALC_AGENT!$C$35<B12,CALC_AGENT!$C$35>=B11),1,0) -> 0 | B11: 90 | C11: 2.299 | D11: 0.0312 | E11: 0.0327 | F11: 0.0336 | G11: 0.0337 | H11: 0.0378 | I11: 0.0383 | J11: 0.0429 | K11: 0.043 | L11: 0.0483 | M11: 0.0538 | N11: 0.0593 | P11: 11 | Q11: =+Q10+1 -> 13 | S11: =IF(AND(CALC_AGENT!$C$35<T12,CALC_AGENT!$C$35>=T11),1,0) -> 1 | T11: 60 | U11: 1.1321 | V11: 0.0387 | W11: 0.0416 | X11: 0.041836 | Y11: =((AA11-W11)/5)+W11 -> 0.04258 | Z11: =((AA11-Y11)/4)+Y11 -> 0.04356 | AA11: 0.0465 | AB11: 0.0514 | AC11: 0.0549 | AD11: 0.0564 | AE11: 0.0614 | AF11: 0.0665 | AG11: 0.0716 | AH11: 0.0768 | AI11: 0.0821 | AJ11: 0.0874 | AK11: 0.0927 | AL11: 0.0981 | AM11: 0.1356 | AN11: 6.5 | AO11: 13
A12: =IF(AND(CALC_AGENT!$C$35<B13,CALC_AGENT!$C$35>=B12),1,0) -> 0 | B12: 100 | C12: 2.345 | D12: 0.0306 | E12: 0.0321 | F12: 0.0329 | G12: 0.0331 | H12: 0.0371 | I12: 0.0376 | J12: 0.042 | K12: 0.422 | L12: 0.0474 | M12: 0.0527 | N12: 0.0582 | P12: 12 | Q12: =+Q11+1 -> 14 | S12: =IF(AND(CALC_AGENT!$C$35<T13,CALC_AGENT!$C$35>=T12),1,0) -> 0 | T12: 70 | U12: 1.1565 | V12: 0.0379 | W12: 0.0407 | X12: 0.040936 | Y12: =((AA12-W12)/5)+W12 -> 0.04166 | Z12: =((AA12-Y12)/4)+Y12 -> 0.04262 | AA12: 0.0455 | AB12: 0.0503 | AC12: 0.0537 | AD12: 0.0552 | AE12: 0.0601 | AF12: 0.0651 | AG12: 0.0701 | AH12: 0.0752 | AI12: 0.0803 | AJ12: 0.0855 | AK12: 0.0908 | AL12: 0.0961 | AM12: 0.1327 | AN12: 7 | AO12: 14
A13: =IF(AND(CALC_AGENT!$C$35<B14,CALC_AGENT!$C$35>=B13),1,0) -> 0 | B13: 110 | C13: 2.391 | D13: 0.03 | E13: 0.0315 | F13: 0.0323 | G13: 0.0324 | H13: 0.0364 | I13: 0.0369 | J13: 0.0412 | K13: 0.0414 | L13: 0.0465 | M13: 0.0517 | N13: 0.057 | S13: =IF(AND(CALC_AGENT!$C$35<T14,CALC_AGENT!$C$35>=T13),1,0) -> 0 | T13: 80 | U13: 1.1809 | V13: 0.0371 | W13: 0.0399 | X13: 0.040136 | Y13: =((AA13-W13)/5)+W13 -> 0.12112 | Z13: =((AA13-Y13)/4)+Y13 -> 0.20234 | AA13: 0.446 | AB13: 0.0493 | AC13: 0.0526 | AD13: 0.0541 | AE13: 0.0589 | AF13: 0.0637 | AG13: 0.0687 | AH13: 0.0736 | AI13: 0.0787 | AJ13: 0.0838 | AK13: 0.0889 | AL13: 0.0941 | AM13: 0.13 | AN13: 7.5 | AO13: 15
A14: =IF(AND(CALC_AGENT!$C$35<B15,CALC_AGENT!$C$35>=B14),1,0) -> 0 | B14: 120 | C14: 2.437 | D14: 0.0295 | E14: 0.0309 | F14: 0.0317 | G14: 0.0318 | H14: 0.0357 | I14: 0.0362 | J14: 0.0404 | K14: 0.0406 | L14: 0.0456 | M14: 0.0507 | N14: 0.056 | S14: =IF(AND(CALC_AGENT!$C$35<T15,CALC_AGENT!$C$35>=T14),1,0) -> 0 | T14: 90 | U14: 1.2053 | V14: 0.0364 | W14: 0.0391 | X14: 0.039336 | Y14: =((AA14-W14)/5)+W14 -> 0.04002 | Z14: =((AA14-Y14)/4)+Y14 -> 0.04094 | AA14: 0.0437 | AB14: 0.0483 | AC14: 0.0516 | AD14: 0.053 | AE14: 0.0577 | AF14: 0.0624 | AG14: 0.0673 | AH14: 0.0721 | AI14: 0.0771 | AJ14: 0.0821 | AK14: 0.0871 | AL14: 0.0922 | AM14: 0.1273 | AN14: 8 | AO14: 16
A15: =IF(AND(CALC_AGENT!$C$35<B16,CALC_AGENT!$C$35>=B15),1,0) -> 0 | B15: 130 | C15: 2.483 | D15: 0.0289 | E15: 0.0303 | F15: 0.0311 | G15: 0.0312 | H15: 0.035 | I15: 0.0355 | J15: 0.0397 | K15: 0.0398 | L15: 0.0447 | M15: 0.0498 | N15: 0.0549 | S15: =IF(AND(CALC_AGENT!$C$35<T16,CALC_AGENT!$C$35>=T15),1,0) -> 0 | T15: 100 | U15: 1.2297 | V15: 0.0357 | W15: 0.0383 | X15: 0.038536 | Y15: =((AA15-W15)/5)+W15 -> 0.0392 | Z15: =((AA15-Y15)/4)+Y15 -> 0.0401 | AA15: 0.0428 | AB15: 0.0473 | AC15: 0.0505 | AD15: 0.0519 | AE15: 0.0565 | AF15: 0.0612 | AG15: 0.0659 | AH15: 0.0707 | AI15: 0.0755 | AJ15: 0.0804 | AK15: 0.0854 | AL15: 0.0904 | AM15: 0.1248 | AN15: 8.5 | AO15: 17
A16: =IF(AND(CALC_AGENT!$C$35<B17,CALC_AGENT!$C$35>=B16),1,0) -> 0 | B16: 140 | C16: 2.529 | D16: 0.0284 | E16: 0.0298 | F16: 0.0305 | G16: 0.0307 | H16: 0.0344 | I16: 0.0349 | J16: 0.039 | K16: 0.0391 | L16: 0.0439 | M16: 0.0489 | N16: 0.0539 | S16: =IF(AND(CALC_AGENT!$C$35<T17,CALC_AGENT!$C$35>=T16),1,0) -> 0 | T16: 110 | U16: 1.2541 | V16: 0.035 | W16: 0.0376 | X16: 0.037836 | Y16: =((AA16-W16)/5)+W16 -> 0.03848 | Z16: =((AA16-Y16)/4)+Y16 -> 0.03936 | AA16: 0.042 | AB16: 0.0464 | AC16: 0.0495 | AD16: 0.0509 | AE16: 0.0554 | AF16: 0.06 | AG16: 0.0647 | AH16: 0.0693 | AI16: 0.0741 | AJ16: 0.0789 | AK16: 0.0837 | AL16: 0.0886 | AM16: 0.1224 | AN16: 9 | AO16: 18
S17: =IF(AND(CALC_AGENT!$C$35<T18,CALC_AGENT!$C$35>=T17),1,0) -> 0 | T17: 120 | U17: 1.2785 | V17: 0.0343 | W17: 0.0369 | X17: 0.037136 | Y17: =((AA17-W17)/5)+W17 -> 0.03776 | Z17: =((AA17-Y17)/4)+Y17 -> 0.03862 | AA17: 0.0412 | AB17: 0.0455 | AC17: 0.0486 | AD17: 0.0499 | AE17: 0.0544 | AF17: 0.0589 | AG17: 0.0634 | AH17: 0.068 | AI17: 0.0727 | AJ17: 0.0774 | AK17: 0.0821 | AL17: 0.0869 | AM17: 0.12 | AN17: 9.5 | AO17: 19
S18: =IF(AND(CALC_AGENT!$C$35<T19,CALC_AGENT!$C$35>=T18),1,0) -> 0 | T18: 130 | U18: 1.3029 | V18: 0.0336 | W18: 0.362 | X18: 0.362236 | Y18: =((AA18-W18)/5)+W18 -> 0.29768 | Z18: =((AA18-Y18)/4)+Y18 -> 0.23336 | AA18: 0.0404 | AB18: 0.0447 | AC18: 0.0477 | AD18: 0.049 | AE18: 0.0534 | AF18: 0.0578 | AG18: 0.0622 | AH18: 0.0667 | AI18: 0.0713 | AJ18: 0.0759 | AK18: 0.0806 | AL18: 0.0853 | AM18: 0.1178 | AN18: 10 | AO18: 20
S19: =IF(AND(CALC_AGENT!$C$35<T20,CALC_AGENT!$C$35>=T19),1,0) -> 0 | T19: 140 | U19: 1.3273 | V19: 0.033 | W19: 0.0355 | X19: 0.035736 | Y19: =((AA19-W19)/5)+W19 -> 0.03634 | Z19: =((AA19-Y19)/4)+Y19 -> 0.03718 | AA19: 0.0397 | AB19: 0.0438 | AC19: 0.0468 | AD19: 0.0481 | AE19: 0.0524 | AF19: 0.0567 | AG19: 0.0611 | AH19: 0.0655 | AI19: 0.007 | AJ19: 0.0745 | AK19: 0.0791 | AL19: 0.0837 | AM19: 0.1156 | AN19: 13.3 | AO19: 21
S20: =IF(AND(CALC_AGENT!$C$35<T21,CALC_AGENT!$C$35>=T20),1,0) -> 0 | T20: 150 | U20: 1.3518 | V20: 0.0324 | W20: 0.0349 | X20: 0.035136 | Y20: =((AA20-W20)/5)+W20 -> 0.0357 | Z20: =((AA20-Y20)/4)+Y20 -> 0.0365 | AA20: 0.0389 | AB20: 0.0431 | AC20: 0.046 | AD20: 0.0472 | AE20: 0.0514 | AF20: 0.0557 | AG20: 0.06 | AH20: 0.0643 | AI20: 0.0687 | AJ20: 0.0732 | AK20: 0.0777 | AL20: 0.0822 | AM20: 0.1135
S21: =IF(AND(CALC_AGENT!$C$35<T22,CALC_AGENT!$C$35>=T21),1,0) -> 0 | T21: 160 | U21: 1.3762 | V21: 0.0319 | W21: 0.0342 | X21: 0.034436 | Y21: =((AA21-W21)/5)+W21 -> 0.035 | Z21: =((AA21-Y21)/4)+Y21 -> 0.0358 | AA21: 0.0382 | AB21: 0.0423 | AC21: 0.0452 | AD21: 0.0464 | AE21: 0.0505 | AF21: 0.0547 | AG21: 0.0589 | AH21: 0.0632 | AI21: 0.0675 | AJ21: 0.0719 | AK21: 0.0763 | AL21: 0.0807 | AM21: 0.1115
S22: =IF(AND(CALC_AGENT!$C$35<T23,CALC_AGENT!$C$35>=T22),1,0) -> 0 | T22: 170 | U22: 1.4006 | V22: 0.0313 | W22: 0.0336 | X22: 0.033836 | Y22: =((AA22-W22)/5)+W22 -> 0.0344 | Z22: =((AA22-Y22)/4)+Y22 -> 0.0352 | AA22: 0.0376 | AB22: 0.0416 | AC22: 0.0444 | AD22: 0.0456 | AE22: 0.0496 | AF22: 0.0537 | AG22: 0.0579 | AH22: 0.0621 | AI22: 0.0663 | AJ22: 0.0706 | AK22: 0.0749 | AL22: 0.0793 | AM22: 0.1096
S23: =IF(AND(CALC_AGENT!$C$35<T24,CALC_AGENT!$C$35>=T23),1,0) -> 0 | T23: 180 | U23: 1.425 | V23: 0.0308 | W23: 0.0331 | X23: 0.033336 | Y23: =((AA23-W23)/5)+W23 -> 0.03386 | Z23: =((AA23-Y23)/4)+Y23 -> 0.03462 | AA23: 0.0369 | AB23: 0.0408 | AC23: 0.0436 | AD23: 0.0448 | AE23: 0.0488 | AF23: 0.0528 | AG23: 0.0569 | AH23: 0.061 | AI23: 0.0652 | AJ23: 0.0694 | AK23: 0.0737 | AL23: 0.078 | AM23: 0.1077
S24: =IF(AND(CALC_AGENT!$C$35<T25,CALC_AGENT!$C$35>=T24),1,0) -> 0 | T24: 190 | U24: 1.4494 | V24: 0.0302 | W24: 0.0325 | X24: 0.032736 | Y24: =((AA24-W24)/5)+W24 -> 0.03326 | Z24: =((AA24-Y24)/4)+Y24 -> 0.03402 | AA24: 0.0363 | AB24: 0.0402 | AC24: 0.0429 | AD24: 0.044 | AE24: 0.048 | AF24: 0.0519 | AG24: 0.0559 | AH24: 0.06 | AI24: 0.0641 | AJ24: 0.0682 | AK24: 0.0724 | AL24: 0.0767 | AM24: 0.1059
S25: =IF(AND(CALC_AGENT!$C$35<T26,CALC_AGENT!$C$35>=T25),1,0) -> 0 | T25: 200 | U25: 1.4738 | V25: 0.0297 | W25: 0.032 | X25: 0.032236 | Y25: =((AA25-W25)/5)+W25 -> 0.03274 | Z25: =((AA25-Y25)/4)+Y25 -> 0.03348 | AA25: 0.0357 | AB25: 0.0395 | AC25: 0.0422 | AD25: 0.0433 | AE25: 0.0472 | AF25: 0.0511 | AG25: 0.055 | AH25: 0.059 | AI25: 0.063 | AJ25: 0.0671 | AK25: 0.0712 | AL25: 0.0754 | AM25: 0.1041
S26: =IF(AND(CALC_AGENT!$C$35<T27,CALC_AGENT!$C$35>=T26),1,0) -> 0 | T26: 210 | U26: 1.4982 | V26: 0.0293 | W26: 0.0315 | X26: 0.031736 | Y26: =((AA26-W26)/5)+W26 -> 0.03222 | Z26: =((AA26-Y26)/4)+Y26 -> 0.03294 | AA26: 0.0351 | AB26: 0.0388 | AC26: 0.0415 | AD26: 0.0426 | AE26: 0.0464 | AF26: 0.0502 | AG26: 0.0541 | AH26: 0.058 | AI26: 0.062 | AJ26: 0.066 | AK26: 0.0701 | AL26: 0.0742 | AM26: 0.1024
S27: =IF(AND(CALC_AGENT!$C$35<T28,CALC_AGENT!$C$35>=T27),1,0) -> 0 | T27: 220 | U27: 1.5226 | V27: 0.0288 | W27: 0.0309 | X27: 0.031136 | Y27: =((AA27-W27)/5)+W27 -> 0.03164 | Z27: =((AA27-Y27)/4)+Y27 -> 0.03238 | AA27: 0.0346 | AB27: 0.0382 | AC27: 0.0408 | AD27: 0.0419 | AE27: 0.0457 | AF27: 0.0494 | AG27: 0.0533 | AH27: 0.0571 | AI27: 0.061 | AJ27: 0.065 | AK27: 0.0689 | AL27: 0.073 | AM27: 0.1008

Sheet COT AGENTES
A1: 1 | B1: FM-200 | G1: MODELO CIL. | H1: DEFAULT | J1: =IF(H4="FM-200",M13,M12) -> 4.52 | L1: 46023 | M1: 1 | N1: 1 | X1: nozzle novec | Y1: 360 | Z1: 9,14 m. | AA1: radio
A2: 2 | B2: FK-5-1-12 | G2: TIPO SIST. | H2: MANIFOLD | M2: DIMENSIONES | N2: 1 | O2: TEMPERATURA | Y2: 180 | Z2: 15 m. | AA2: radio
A3: 3 | B3: SISTEMA | G3: CILINDROS CANT. | H3: 1 | L3: LARGO | M3: 1 | N3: =M3*CALC_AGENT!$E$4 -> 3.28083 | O3: MIN Cº | X3: nozzle fm | Y3: 360 | Z3: 8,7 m. | AA3: radio
A4: 4 | B4: MANIFOLD | F4: =IF($H$4="FM-200","4,87","4,3") -> 4,3 | G4: AGENTE | H4: FK-5-1-12 | L4: ANCHO | M4: 1 | N4: =M4*CALC_AGENT!$E$4 -> 3.28083 | O4: 18 | Y4: 180 | Z4: 10,05 m. | AA4: radio
A5: 5 | B5: RESERVA | G5: CANTIDAD Lbs. | H5: =ROUND(IF(H4="FM-200",CALC_AGENT!C82,IF(H4="FK-5-1-12",CALC_AGENT!M82)),0) -> 2 | I5: =IF(IF(H4="FM-200",[1]TABLA!C16,IF('COT AGENTES'!H4="FK-5-1-12",[1]TABLA!H16))>0,"SUPERA LIMITE DE AGENTE","OK") -> OK | L5: ALTO | M5: 1 | N5: =M5*CALC_AGENT!$E$4 -> 3.28083 | O5: MAX Cº
A6: 6 | B6: MAIN RESERVE | G6: COD. CIL. | H6: =IFERROR(VLOOKUP($B94,'BDD_SISTEMAS- MANIFOLD'!$B:$M,'COT AGENTES'!H$18,0),"") -> 445732 | L6: PISO FALSO | N6: =M6*CALC_AGENT!$E$4 -> 0 | O6: 27 | X6: nozzle | Y6: =VLOOKUP($H$6,[1]Datos!S11:T18,2,0)*$H$3 -> 1
A7: 7 | B7: Actualizar Stock | G7: CONEXIÓN DESCARGA | H7: FLEXIBLE | L7: CIELO FALSO | N7: =M7*CALC_AGENT!$E$4 -> 0 | X7: piso | Y7: =$Y$6*$Z$7 -> 0 | Z7: =IF($M$6=0,0,1) -> 0
A8: 8 | B8: -OPCIONAL | L8: ALTO TOTAL | M8: =SUM(M5+M6+M7) -> 1 | N8: =M8*CALC_AGENT!$E$4 -> 3.28083 | X8: cielo | Y8: =$Y$6*$Z$8 -> 0 | Z8: =IF($M$7=0,0,1) -> 0
A9: 9 | B9: SISTEMA MANIFOLD | H9: METROS (msnm) | I9: =[1]INGRESO_DATOS_SALA!I4 | L9: AREA | M9: =M4*M3 -> 1 | N9: =M9*CALC_AGENT!$E$4 -> 3.28083 | X9: Altura Nozz | Y9: =IF($M$5<$F$4,0,$Y$6) -> 0
A10: 10 | H10: 1 | L10: VOLUMEN | M10: =ROUND(M9*M8,3) -> 1 | N10: =M10*CALC_AGENT!$E$4 -> 3.28083 | X10: total nozzle | Y10: =SUM($Y$6:$Y$9) -> 1
H11: PIES | L11: Nozzle | M11: =Y10 -> 1 | X11: Kg | Y11: Libras
B12: DEFAULT | C12: =IF($H$4="FM-200",[1]TABLA!B15,IF($H$4="FK-5-1-12",[1]TABLA!G15)) -> TANK SIZE 8L | H12: =H10*CALC_AGENT!$E$4 -> 3.28083 | L12: Conc. Novec | M12: 4.52 | X12: 1 | Y12: =X12*2.20462262 -> 2.2046226
B13: TANK SIZE 8L | C13: TANK SIZE 8L | H13: Nombre de la sala | L13: Conc. FM200 | M13: 8.1
B14: TANK SIZE 16L | C14: TANK SIZE 16L | H14: AAA | L14: =+K18+1 -> 12
B15: TANK SIZE 32L | C15: TANK SIZE 32L | L15: Capacidad cil | M15: =IF(H4="FM-200",VLOOKUP(H6,[1]TABLA!$A$20:$D$27,4,0),IF(H4="FK-5-1-12",VLOOKUP(H6,[1]TABLA!$F$20:$I$27,4,0))) -> 21
B16: TANK SIZE 52L | C16: TANK SIZE 52L | L16: Llenado Cil | M16: =(H5/H3)/M15 -> 0.095238095
B17: TANK SIZE 106L | C17: TANK SIZE 106L
B18: TANK SIZE 147L | C18: TANK SIZE 147L | G18: 7 | H18: =+G18+1 -> 8 | I18: =+H18+1 -> 9 | J18: =+I18+1 -> 10 | K18: =+J18+1 -> 11
B19: TANK SIZE 180L | C19: TANK SIZE 180L | H19: =" SISTEMA / "&$H$14&" Dimensiones: "&$M$3&" x "&$M$4&" x "&$M$5&" m. "&"Piso Falso: "&$M$6&" m. "&"Cielo Falso: "&$M$7&" m. "&"Volumen: "&$M$10&" m3." -> SISTEMA / AAA Dimensiones: 1 x 1 x 1 m. Piso Falso: m. Cielo Falso: m. Volumen: 1 m3. | M19: 1 | N19: TOTAL
B20: TANK SIZE 343L | C20: TANK SIZE 343L | H20: ="Agente Limpio: "&$H$4&" Concentración: "&$J$1&"% Temperatura: "&"Min: "&$O$4&"°C "&"Max: "&$O$6&"°C Altura Geográfica: "&$H$10&" msnm." -> Agente Limpio: FK-5-1-12 Concentración: 4,52% Temperatura: Min: 18°C Max: 27°C Altura Geográfica: 1 msnm. | L20: Para espacios que contengan riesgos eléctricos mayores a 480 voltios, se deben desenergizar los equipos antes de la descarga. En caso de que los equipos tienen que seguir energizados comunicarse con su ejecutivo comercial. | M20: =$M$16 -> 0.095238095 | N20: =SUM(N22:N46) -> 109.88
B21: SISTEMA | C21: =VLOOKUP(H1,B12:C20,2,0) -> TANK SIZE 8L | E21: SISTEMA | F21: Ítem | G21: Marca | H21: Codigo | I21: Descripción | J21: U/M | K21: Cant. | L21: Entrega | M21: V.Unitario | N21: V.Total | O21: STOCK
B22: =$B$21&C22&$H$4&$H$3&"-"&F22 -> SISTEMATANK SIZE 8LFK-5-1-121-1 | C22: =C21 -> TANK SIZE 8L | F22: 1 | G22: =IFERROR(VLOOKUP($B22,'BDD_SISTEMAS- MANIFOLD'!$B:$M,'COT AGENTES'!G$18,0),"") -> ANSUL | H22: =IFERROR(VLOOKUP($B22,'BDD_SISTEMAS- MANIFOLD'!$B:$M,'COT AGENTES'!H$18,0),"") -> AGLIMP-RECARGA-00 | I22: =IFERROR(VLOOKUP($B22,'BDD_SISTEMAS- MANIFOLD'!$B:$M,'COT AGENTES'!I$18,0),"") -> SERVICIO DE CARGA DE AGENTE 8L | J22: =IFERROR(VLOOKUP($B22,'BDD_SISTEMAS- MANIFOLD'!$B:$M,'COT AGENTES'!J$18,0),"") -> c/u. | K22: =IFERROR(VLOOKUP($B22,'BDD_SISTEMAS- MANIFOLD'!$B:$M,'COT AGENTES'!K$18,0),"") -> 1 | M22: =IFERROR(VLOOKUP(B22,'BDD_SISTEMAS- MANIFOLD'!B1:N1242,13,0),"") -> 1 | N22: =IFERROR((M22*K22),"") -> 1 | O22: =IFERROR(VLOOKUP(H22,[1]STOCK!$A:$B,4,0),"")
B23: =$B$21&C23&$H$4&$H$3&"-"&F23 -> SISTEMATANK SIZE 8LFK-5-1-121-2 | C23: =C22 -> TANK SIZE 8L | F23: =+F22+1 -> 2 | G23: =IFERROR(VLOOKUP($B23,'BDD_SISTEMAS- MANIFOLD'!$B:$M,'COT AGENTES'!G$18,0),"") -> ANSUL | H23: =IFERROR(VLOOKUP($B23,'BDD_SISTEMAS- MANIFOLD'!$B:$M,'COT AGENTES'!H$18,0),"") -> 445732 | I23: =IFERROR(VLOOKUP($B23,'BDD_SISTEMAS- MANIFOLD'!$B:$M,'COT AGENTES'!I$18,0),"") -> TANK SIZE 8L, Fill: 9-21 lb. | J23: =IFERROR(VLOOKUP($B23,'BDD_SISTEMAS- MANIFOLD'!$B:$M,'COT AGENTES'!J$18,0),"") -> c/u. | K23: =IFERROR(VLOOKUP($B23,'BDD_SISTEMAS- MANIFOLD'!$B:$M,'COT AGENTES'!K$18,0),"") -> 1 | M23: =IFERROR(VLOOKUP(B23,'BDD_SISTEMAS- MANIFOLD'!B2:N1242,13,0),"") -> 1 | N23: =IFERROR((M23*K23),"") -> 1 | O23: =IFERROR(VLOOKUP(H23,[1]STOCK!$A:$B,4,0),"")
B24: =$B$21&C24&$H$4&$H$3&"-"&F24 -> SISTEMATANK SIZE 8LFK-5-1-121-3 | C24: =C23 -> TANK SIZE 8L | F24: =+F23+1 -> 3 | G24: =IFERROR(VLOOKUP($B24,'BDD_SISTEMAS- MANIFOLD'!$B:$M,'COT AGENTES'!G$18,0),"") -> ANSUL | H24: =IFERROR(VLOOKUP($B24,'BDD_SISTEMAS- MANIFOLD'!$B:$M,'COT AGENTES'!H$18,0),"") -> FK-5-1-12 | I24: =IFERROR(VLOOKUP($B24,'BDD_SISTEMAS- MANIFOLD'!$B:$M,'COT AGENTES'!I$18,0),"") -> FK-5-1-12 FLUID FACTORY FILL PER L | J24: =IFERROR(VLOOKUP($B24,'BDD_SISTEMAS- MANIFOLD'!$B:$M,'COT AGENTES'!J$18,0),"") -> c/u. | K24: =IFERROR(VLOOKUP($B24,'BDD_SISTEMAS- MANIFOLD'!$B:$M,'COT AGENTES'!K$18,0),"") -> 2 | M24: =IFERROR(VLOOKUP(B24,'BDD_SISTEMAS- MANIFOLD'!B3:N1242,13,0),"") -> 1 | N24: =IFERROR((M24*K24),"") -> 2 | O24: =IFERROR(VLOOKUP(H24,[1]STOCK!$A:$B,4,0),"")
B25: =$B$21&C25&$H$4&$H$3&"-"&F25 -> SISTEMATANK SIZE 8LFK-5-1-121-4 | C25: =C24 -> TANK SIZE 8L | F25: =+F24+1 -> 4 | G25: =IFERROR(VLOOKUP($B25,'BDD_SISTEMAS- MANIFOLD'!$B:$M,'COT AGENTES'!G$18,0),"") -> ANSUL | H25: =IFERROR(VLOOKUP($B25,'BDD_SISTEMAS- MANIFOLD'!$B:$M,'COT AGENTES'!H$18,0),"") -> 302207021 | I25: =IFERROR(VLOOKUP($B25,'BDD_SISTEMAS- MANIFOLD'!$B:$M,'COT AGENTES'!I$18,0),"") -> Pressure Gauge, FK-5-1-12 | J25: =IFERROR(VLOOKUP($B25,'BDD_SISTEMAS- MANIFOLD'!$B:$M,'COT AGENTES'!J$18,0),"") -> c/u. | K25: =IFERROR(VLOOKUP($B25,'BDD_SISTEMAS- MANIFOLD'!$B:$M,'COT AGENTES'!K$18,0),"") -> 1 | M25: =IFERROR(VLOOKUP(B25,'BDD_SISTEMAS- MANIFOLD'!B4:N1242,13,0),"") -> 1 | N25: =IFERROR((M25*K25),"") -> 1 | O25: =IFERROR(VLOOKUP(H25,[1]STOCK!$A:$B,4,0),"")
B26: =$B$21&C26&$H$4&$H$3&"-"&F26 -> SISTEMATANK SIZE 8LFK-5-1-121-5 | C26: =C25 -> TANK SIZE 8L | F26: =+F25+1 -> 5 | G26: =IFERROR(VLOOKUP($B26,'BDD_SISTEMAS- MANIFOLD'!$B:$M,'COT AGENTES'!G$18,0),"") -> ANSUL | H26: =IFERROR(VLOOKUP($B26,'BDD_SISTEMAS- MANIFOLD'!$B:$M,'COT AGENTES'!H$18,0),"") -> 314207207 | I26: =IFERROR(VLOOKUP($B26,'BDD_SISTEMAS- MANIFOLD'!$B:$M,'COT AGENTES'!I$18,0),"") -> SAPPHIRE Label 8/16/52L UL/FM | J26: =IFERROR(VLOOKUP($B26,'BDD_SISTEMAS- MANIFOLD'!$B:$M,'COT AGENTES'!J$18,0),"") -> c/u. | K26: =IFERROR(VLOOKUP($B26,'BDD_SISTEMAS- MANIFOLD'!$B:$M,'COT AGENTES'!K$18,0),"") -> 1 | M26: =IFERROR(VLOOKUP(B26,'BDD_SISTEMAS- MANIFOLD'!B5:N1242,13,0),"") -> 1 | N26: =IFERROR((M26*K26),"") -> 1 | O26: =IFERROR(VLOOKUP(H26,[1]STOCK!$A:$B,4,0),"")
B27: =$B$21&C27&$H$4&$H$3&"-"&F27 -> SISTEMATANK SIZE 8LFK-5-1-121-6 | C27: =C26 -> TANK SIZE 8L | F27: =+F26+1 -> 6 | G27: =IFERROR(VLOOKUP($B27,'BDD_SISTEMAS- MANIFOLD'!$B:$M,'COT AGENTES'!G$18,0),"") -> ANSUL | H27: =IFERROR(VLOOKUP($B27,'BDD_SISTEMAS- MANIFOLD'!$B:$M,'COT AGENTES'!H$18,0),"") -> 570585 | I27: =IFERROR(VLOOKUP($B27,'BDD_SISTEMAS- MANIFOLD'!$B:$M,'COT AGENTES'!I$18,0),"") -> Cylinder Low Pressure Switch | J27: =IFERROR(VLOOKUP($B27,'BDD_SISTEMAS- MANIFOLD'!$B:$M,'COT AGENTES'!J$18,0),"") -> c/u. | K27: =IFERROR(VLOOKUP($B27,'BDD_SISTEMAS- MANIFOLD'!$B:$M,'COT AGENTES'!K$18,0),"") -> 1 | M27: =IFERROR(VLOOKUP(B27,'BDD_SISTEMAS- MANIFOLD'!B6:N1243,13,0),"") -> 1 | N27: =IFERROR((M27*K27),"") -> 1 | O27: =IFERROR(VLOOKUP(H27,[1]STOCK!$A:$B,4,0),"")
B28: =$B$21&C28&$H$4&$H$3&"-"&F28 -> SISTEMATANK SIZE 8LFK-5-1-121-7 | C28: =C27 -> TANK SIZE 8L | F28: =+F27+1 -> 7 | G28: =IFERROR(VLOOKUP($B28,'BDD_SISTEMAS- MANIFOLD'!$B:$M,'COT AGENTES'!G$18,0),"") -> ANSUL | H28: =IFERROR(VLOOKUP($B28,'BDD_SISTEMAS- MANIFOLD'!$B:$M,'COT AGENTES'!H$18,0),"") -> 304205030 | I28: =IFERROR(VLOOKUP($B28,'BDD_SISTEMAS- MANIFOLD'!$B:$M,'COT AGENTES'!I$18,0),"") -> Electric Actuator Shipping Assembly | J28: =IFERROR(VLOOKUP($B28,'BDD_SISTEMAS- MANIFOLD'!$B:$M,'COT AGENTES'!J$18,0),"") -> c/u. | K28: =IFERROR(VLOOKUP($B28,'BDD_SISTEMAS- MANIFOLD'!$B:$M,'COT AGENTES'!K$18,0),"") -> 1 | M28: =IFERROR(VLOOKUP(B28,'BDD_SISTEMAS- MANIFOLD'!B7:N1244,13,0),"") -> 1 | N28: =IFERROR((M28*K28),"") -> 1 | O28: =IFERROR(VLOOKUP(H28,[1]STOCK!$A:$B,4,0),"")
B29: =$B$21&C29&$H$4&$H$3&"-"&F29 -> SISTEMATANK SIZE 8LFK-5-1-121-8 | C29: =C28 -> TANK SIZE 8L | F29: =+F28+1 -> 8 | G29: =IFERROR(VLOOKUP($B29,'BDD_SISTEMAS- MANIFOLD'!$B:$M,'COT AGENTES'!G$18,0),"") -> ANSUL | H29: =IFERROR(VLOOKUP($B29,'BDD_SISTEMAS- MANIFOLD'!$B:$M,'COT AGENTES'!H$18,0),"") -> A1638150HY | I29: =IFERROR(VLOOKUP($B29,'BDD_SISTEMAS- MANIFOLD'!$B:$M,'COT AGENTES'!I$18,0),"") -> Local Manual Actuator | J29: =IFERROR(VLOOKUP($B29,'BDD_SISTEMAS- MANIFOLD'!$B:$M,'COT AGENTES'!J$18,0),"") -> c/u. | K29: =IFERROR(VLOOKUP($B29,'BDD_SISTEMAS- MANIFOLD'!$B:$M,'COT AGENTES'!K$18,0),"") -> 1 | M29: =IFERROR(VLOOKUP(B29,'BDD_SISTEMAS- MANIFOLD'!B8:N1245,13,0),"") -> 1 | N29: =IFERROR((M29*K29),"") -> 1 | O29: =IFERROR(VLOOKUP(H29,[1]STOCK!$A:$B,4,0),"")
B30: =$B$21&C30&$H$4&$H$3&"-"&F30 -> SISTEMATANK SIZE 8LFK-5-1-121-9 | C30: =C29 -> TANK SIZE 8L | F30: =+F29+1 -> 9 | G30: =IFERROR(VLOOKUP($B30,'BDD_SISTEMAS- MANIFOLD'!$B:$M,'COT AGENTES'!G$18,0),"") -> ANSUL | H30: =IFERROR(VLOOKUP($B30,'BDD_SISTEMAS- MANIFOLD'!$B:$M,'COT AGENTES'!H$18,0),"") -> 570085-R2 | I30: =IFERROR(VLOOKUP($B30,'BDD_SISTEMAS- MANIFOLD'!$B:$M,'COT AGENTES'!I$18,0),"") -> Tank Bracket Assembly (Fits 20, 50 & 90 lb. Tanks) | J30: =IFERROR(VLOOKUP($B30,'BDD_SISTEMAS- MANIFOLD'!$B:$M,'COT AGENTES'!J$18,0),"") -> c/u. | K30: =IFERROR(VLOOKUP($B30,'BDD_SISTEMAS- MANIFOLD'!$B:$M,'COT AGENTES'!K$18,0),"") -> 1 | M30: =IFERROR(VLOOKUP(B30,'BDD_SISTEMAS- MANIFOLD'!B9:N1246,13,0),"") -> 1 | N30: =IFERROR((M30*K30),"") -> 1 | O30: =IFERROR(VLOOKUP(H30,[1]STOCK!$A:$B,4,0),"")
B31: =$B$21&C31&$H$4&$H$3&"-"&F31 -> SISTEMATANK SIZE 8LFK-5-1-121-10 | C31: =C30 -> TANK SIZE 8L | F31: =+F30+1 -> 10 | G31: =IFERROR(VLOOKUP($B31,'BDD_SISTEMAS- MANIFOLD'!$B:$M,'COT AGENTES'!G$18,0),"") -> ANSUL | H31: =IFERROR(VLOOKUP($B31,'BDD_SISTEMAS- MANIFOLD'!$B:$M,'COT AGENTES'!H$18,0),"") -> 17549OK | I31: =IFERROR(VLOOKUP($B31,'BDD_SISTEMAS- MANIFOLD'!$B:$M,'COT AGENTES'!I$18,0),"") -> Nozzle, según memoria de calculo | J31: =IFERROR(VLOOKUP($B31,'BDD_SISTEMAS- MANIFOLD'!$B:$M,'COT AGENTES'!J$18,0),"") -> c/u. | K31: =IFERROR(VLOOKUP($B31,'BDD_SISTEMAS- MANIFOLD'!$B:$M,'COT AGENTES'!K$18,0),"") -> 1 | M31: =IFERROR(VLOOKUP(B31,'BDD_SISTEMAS- MANIFOLD'!B10:N1247,13,0),"") -> 1 | N31: =IFERROR((M31*K31),"") -> 1 | O31: =IFERROR(VLOOKUP(H31,[1]STOCK!$A:$B,4,0),"")
B32: =$B$21&C32&$H$4&$H$3&"-"&F32 -> SISTEMATANK SIZE 8LFK-5-1-121-11 | C32: =C31 -> TANK SIZE 8L | F32: =+F31+1 -> 11 | G32: =IFERROR(VLOOKUP($B32,'BDD_SISTEMAS- MANIFOLD'!$B:$M,'COT AGENTES'!G$18,0),"") -> ANSUL | H32: =IFERROR(VLOOKUP($B32,'BDD_SISTEMAS- MANIFOLD'!$B:$M,'COT AGENTES'!H$18,0),"") -> 314207101-R2 | I32: =IFERROR(VLOOKUP($B32,'BDD_SISTEMAS- MANIFOLD'!$B:$M,'COT AGENTES'!I$18,0),"") -> DOOR NOTICE (LESS THAN NOAEL) | J32: =IFERROR(VLOOKUP($B32,'BDD_SISTEMAS- MANIFOLD'!$B:$M,'COT AGENTES'!J$18,0),"") -> c/u. | K32: =IFERROR(VLOOKUP($B32,'BDD_SISTEMAS- MANIFOLD'!$B:$M,'COT AGENTES'!K$18,0),"") -> 1 | M32: =IFERROR(VLOOKUP(B32,'BDD_SISTEMAS- MANIFOLD'!B11:N1248,13,0),"") -> 1 | N32: =IFERROR((M32*K32),"") -> 1 | O32: =IFERROR(VLOOKUP(H32,[1]STOCK!$A:$B,4,0),"")
B33: =$B$21&C33&$H$4&$H$3&"-"&F33 -> SISTEMATANK SIZE 8LFK-5-1-121-12 | C33: =C32 -> TANK SIZE 8L | F33: =+F32+1 -> 12 | G33: =IFERROR(VLOOKUP($B33,'BDD_SISTEMAS- MANIFOLD'!$B:$M,'COT AGENTES'!G$18,0),"") -> ANSUL | H33: =IFERROR(VLOOKUP($B33,'BDD_SISTEMAS- MANIFOLD'!$B:$M,'COT AGENTES'!H$18,0),"") -> 314207103-R2 | I33: =IFERROR(VLOOKUP($B33,'BDD_SISTEMAS- MANIFOLD'!$B:$M,'COT AGENTES'!I$18,0),"") -> MANUAL RELEASE SIGN | J33: =IFERROR(VLOOKUP($B33,'BDD_SISTEMAS- MANIFOLD'!$B:$M,'COT AGENTES'!J$18,0),"") -> c/u. | K33: =IFERROR(VLOOKUP($B33,'BDD_SISTEMAS- MANIFOLD'!$B:$M,'COT AGENTES'!K$18,0),"") -> 1 | M33: =IFERROR(VLOOKUP(B33,'BDD_SISTEMAS- MANIFOLD'!B12:N1249,13,0),"") -> 1 | N33: =IFERROR((M33*K33),"") -> 1 | O33: =IFERROR(VLOOKUP(H33,[1]STOCK!$A:$B,4,0),"")
B34: =$B$21&C34&$H$4&$H$3&"-"&F34 -> SISTEMATANK SIZE 8LFK-5-1-121-13 | C34: =C33 -> TANK SIZE 8L | F34: =+F33+1 -> 13 | G34: =IFERROR(VLOOKUP($B34,'BDD_SISTEMAS- MANIFOLD'!$B:$M,'COT AGENTES'!G$18,0),"") -> ANSUL | H34: =IFERROR([1]Datos!$B$97,"") -> 570539-R2 | I34: =IFERROR([1]Datos!C97,"") -> Flexible Discharge Hose, 1 in. | J34: =IFERROR(VLOOKUP($B34,'BDD_SISTEMAS- MANIFOLD'!$B:$M,'COT AGENTES'!J$18,0),"") -> c/u. | K34: =IFERROR(VLOOKUP($B34,'BDD_SISTEMAS- MANIFOLD'!$B:$M,'COT AGENTES'!K$18,0),"") -> 1 | M34: =IFERROR(VLOOKUP(H34,[1]Hoja7!$C$5:$F$85,4,0),"") -> 93.88 | N34: =IFERROR((M34*K34),"") -> 93.88 | O34: =IFERROR(VLOOKUP(H34,[1]STOCK!$A:$B,4,0),"")
B35: =$B$21&C35&$H$4&$H$3&"-"&F35 -> SISTEMATANK SIZE 8LFK-5-1-121-14 | C35: =C34 -> TANK SIZE 8L | F35: =+F34+1 -> 14 | G35: =IFERROR(VLOOKUP($B35,'BDD_SISTEMAS- MANIFOLD'!$B:$M,'COT AGENTES'!G$18,0),"") -> 0 | H35: =IFERROR(VLOOKUP($B35,'BDD_SISTEMAS- MANIFOLD'!$B:$M,'COT AGENTES'!H$18,0),"") -> 0 | I35: =IFERROR(VLOOKUP($B35,'BDD_SISTEMAS- MANIFOLD'!$B:$M,'COT AGENTES'!I$18,0),"") -> 0 | J35: =IFERROR(VLOOKUP($B35,'BDD_SISTEMAS- MANIFOLD'!$B:$M,'COT AGENTES'!J$18,0),"") -> 0 | K35: =IFERROR(VLOOKUP($B35,'BDD_SISTEMAS- MANIFOLD'!$B:$M,'COT AGENTES'!K$18,0),"") -> 0 | M35: =IFERROR(VLOOKUP(B35,'BDD_SISTEMAS- MANIFOLD'!B14:N1251,13,0),"") -> 1 | N35: =IFERROR((M35*K35),"") -> 0 | O35: =IFERROR(VLOOKUP(H35,[1]STOCK!$A:$B,4,0),"")
B36: =$B$21&C36&$H$4&$H$3&"-"&F36 -> SISTEMATANK SIZE 8LFK-5-1-121-15 | C36: =C35 -> TANK SIZE 8L | F36: =+F35+1 -> 15 | G36: =IFERROR(VLOOKUP($B36,'BDD_SISTEMAS- MANIFOLD'!$B:$M,'COT AGENTES'!G$18,0),"") -> ANSUL | H36: =IFERROR(VLOOKUP($B36,'BDD_SISTEMAS- MANIFOLD'!$B:$M,'COT AGENTES'!H$18,0),"") -> 437900 | I36: =IFERROR(VLOOKUP($B36,'BDD_SISTEMAS- MANIFOLD'!$B:$M,'COT AGENTES'!I$18,0),"") -> Switch, Pressure, 3PDT | J36: =IFERROR(VLOOKUP($B36,'BDD_SISTEMAS- MANIFOLD'!$B:$M,'COT AGENTES'!J$18,0),"") -> c/u. | K36: =IFERROR(VLOOKUP($B36,'BDD_SISTEMAS- MANIFOLD'!$B:$M,'COT AGENTES'!K$18,0),"") -> 1 | M36: =IFERROR(VLOOKUP(B36,'BDD_SISTEMAS- MANIFOLD'!B15:N1252,13,0),"") -> 1 | N36: =IFERROR((M36*K36),"") -> 1 | O36: =IFERROR(VLOOKUP(H36,[1]STOCK!$A:$B,4,0),"")
B37: =$B$21&C37&$H$4&$H$3&"-"&F37 -> SISTEMATANK SIZE 8LFK-5-1-121-16 | C37: =C36 -> TANK SIZE 8L | F37: =+F36+1 -> 16 | G37: =IFERROR(VLOOKUP($B37,'BDD_SISTEMAS- MANIFOLD'!$B:$M,'COT AGENTES'!G$18,0),"") -> ANSUL | H37: =IFERROR(VLOOKUP($B37,'BDD_SISTEMAS- MANIFOLD'!$B:$M,'COT AGENTES'!H$18,0),"") -> 73597 | I37: =IFERROR(VLOOKUP($B37,'BDD_SISTEMAS- MANIFOLD'!$B:$M,'COT AGENTES'!I$18,0),"") -> Acutation Hose, 16 in., 1/4 in. NPT x 7/16-20 in. F Flare | J37: =IFERROR(VLOOKUP($B37,'BDD_SISTEMAS- MANIFOLD'!$B:$M,'COT AGENTES'!J$18,0),"") -> c/u. | K37: =IFERROR(VLOOKUP($B37,'BDD_SISTEMAS- MANIFOLD'!$B:$M,'COT AGENTES'!K$18,0),"") -> 1 | M37: =IFERROR(VLOOKUP(B37,'BDD_SISTEMAS- MANIFOLD'!B16:N1253,13,0),"") -> 1 | N37: =IFERROR((M37*K37),"") -> 1 | O37: =IFERROR(VLOOKUP(H37,[1]STOCK!$A:$B,4,0),"")
